Workbook

Sheet Overview
B2: This is a spreadsheet which might prove useful to paste output data from ViCTA. It will automate much of the data summarising and minimise the laborious copying and pasting of data.
B4: It can be used to collate results and present charts.
B6: The spreadsheet is colour coded to indicate the data types
B8: Blue tab: | C8: this is where the combinations for strain type and treatment type are given.
C9: You can fill your own strains and treatments and the the matrix A-L to indicate which tab the data output from victa should be pasted into.
B10: Green tabs: | C10: These tabs are used to paste the results from ViCTA into. Data should be pasted every 25 steps, at the vertical points highlighted in green.
C11: If the data are pasted into the correct areas, the summary tabs will be able to automatically calculate most of the results.
B12: Yellow tab: | C12: These tabs summarise the data pasted into A-L and generate totals. These totals can be manually copied into the 'For chart' regions in the summary tabs and they will automatically generate charts.
C13: Pink highlighted areas in yellow tab summaries are data which are directly used to generate the charts in the red tabs
B14: Red tabs: | C14: These tabs show charts generated from the summary totals in they yellow tabbed regions.
B17: Note: There will be some modifications required to the summary totals (averages, medians) because the number of reps might be different for different strains. Please modify the cell ranges in these regions as appropriate
C18: If have tried to put comments at appropriate points in the excel chart to aid data analysis and calculations
B20: Note: | C20: Cells which may require manual adjustment of ranges are highlighted with the following colour: | O20: Any cells with this colour background should be checked to see if the range corresponds to the number of reps performed. The range should be amended if necessary
B28: Hope this is of some help. Jeff Jones
B29: McCall Group LSTM

Sheet file combos
D11: converted:
D12: 1 | E12: 2 | F12: 3 | G12: 4 | H12: 5 | I12: 6 | J12: 7 | K12: 8 | L12: 9 | M12: 10 | N12: 11 | O12: 12 | P12: 13 | Q12: 14 | R12: 15 | S12: 16 | T12: 17 | U12: 18 | V12: 19 | W12: 20
C13: Combo | D13: FAUT | E13: FAP3 | F13: FAOSP | H13: FUUT | I13: FUP3 | J13: FUOSP
C14: Rep Count | D14: A | E14: B | F14: C | G14: D | H14: E | I14: F | J14: G | K14: H | L14: I | M14: J | N14: K | O14: L | P14: M | Q14: N | R14: O | S14: P | T14: Q | U14: R | V14: S | W14: T
C15: 1 | D15: 55 | E15: 59 | F15: 62 | H15: 46 | I15: 49 | J15: 52
C16: 2 | D16: 56 | E16: 60 | F16: 63 | H16: 47 | I16: 50 | J16: 53 | Y16: total number of exps
C17: 3 | D17: 57 | E17: 61 | F17: 64 | H17: 48 | I17: 51 | J17: 54
C18: 4 | D18: 76 | E18: 82 | F18: 79 | H18: 66 | I18: 72 | J18: 69 | Y18: =COUNTA(D15:O35) -> 126 | Z18: experiments
C19: 5 | D19: 77 | E19: 83 | F19: 80 | H19: 67 | I19: 73 | J19: 70
C20: 6 | D20: 78 | E20: 84 | F20: 81 | H20: 68 | I20: 74 | J20: 71
C21: 7 | D21: 109 | E21: 103 | F21: 106 | H21: 85 | I21: 91 | J21: 88
C22: 8 | D22: 110 | E22: 104 | F22: 107 | H22: 86 | I22: 92 | J22: 89
C23: 9 | D23: 111 | E23: 105 | F23: 108 | H23: 87 | I23: 93 | J23: 90
C24: 10 | D24: 120 | E24: 112 | F24: 116 | H24: 100 | I24: 94 | J24: 97
C25: 11 | D25: 121 | E25: 113 | F25: 117 | H25: 101 | I25: 95 | J25: 98
C26: 12 | D26: 122 | E26: 114 | F26: 119 | H26: 102 | I26: 96 | J26: 99
C27: 13 | D27: 196 | E27: 193 | F27: 190 | H27: 169 | I27: 166 | J27: 163
C28: 14 | D28: 197 | E28: 194 | F28: 191 | H28: 170 | I28: 167 | J28: 164
C29: 15 | D29: 198 | E29: 195 | F29: 192 | H29: 171 | I29: 168 | J29: 165
C30: 16 | D30: 211 | E30: 205 | F30: 199 | H30: 178 | I30: 175 | J30: 172
... C35: 21 | D35: 216 | E35: 210 | F35: 204 | H35: 189 | I35: 186 | J35: 183
C36: 22
C37: 23
C38: 199
C39: 25
C40: 26
C41: 27
C42: 28
C43: 29
C44: 30
C45: 31
C46: 32
C47: 33
... C65: 51
C66: Total Reps performed | D66: 21 | E66: 21 | F66: 21 | H66: 21 | I66: 21 | J66: 21
B74: Test Dates
C75: Combo | D75: =D13 -> FAUT | E75: =E13 -> FAP3 | F75: =F13 -> FAOSP | G75: =G13 -> 0 | H75: =H13 -> FUUT | I75: =I13 -> FUP3 | J75: =J13 -> FUOSP | K75: =K13 -> 0 | ... W75: =W13 -> 0
C76: Rep Count | D76: A | E76: B | F76: C | G76: D | H76: E | I76: F | J76: G | K76: H | L76: I | M76: J | N76: K | O76: L | P76: =P14 -> M | Q76: =Q14 -> N | R76: =R14 -> O | S76: =S14 -> P | T76: =T14 -> Q | U76: =U14 -> R | V76: =V14 -> S | W76: =W14 -> T
C77: 1 | D77: 44900
C78: 2
...

Sheet A
A1: Video_File_Analysed | B1: IMG_0055_FA_UT_071222.mp4
A2: R0 | B2: 0 | C2: 0 | D2: 3 | E2: 0 | F2: 0 | G2: 2 | H2: 2 | I2: 1 | J2: 0 | K2: 3 | L2: 5 | M2: 0 | N2: 0 | O2: 6 | P2: 12 | Q2: 0 | R2: 0 | S2: 0 | T2: 0 | U2: 0 | V2: 0 | W2: 0 | X2: 4 | Y2: 6 | Z2: 0 | AA2: 0 | AB2: 0 | AC2: 0 | AD2: 5 | AE2: 0 | AF2: 0 | AG2: 0 | AH2: 0 | AI2: 0 | AJ2: 0 | AK2: 0
A3: R1 | B3: 18 | C3: 36 | D3: 41 | E3: 6 | F3: 12 | G3: 21 | H3: 35 | I3: 66 | J3: 48 | K3: 28 | L3: 29 | M3: 43 | N3: 21 | O3: 54 | P3: 32 | Q3: 46 | R3: 91 | S3: 70 | T3: 19 | U3: 11 | V3: 0 | W3: 72 | X3: 150 | Y3: 87 | Z3: 59 | AA3: 42 | AB3: 44 | AC3: 82 | AD3: 85 | AE3: 1 | AF3: 0 | AG3: 7 | AH3: 6 | AI3: 45 | AJ3: 28 | AK3: 41
A4: R2 | B4: 0 | C4: 13 | D4: 4 | E4: 0 | F4: 0 | G4: 13 | H4: 7 | I4: 10 | J4: 0 | K4: 20 | L4: 15 | M4: 45 | N4: 70 | O4: 72 | P4: 53 | Q4: 24 | R4: 27 | S4: 29 | T4: 0 | U4: 0 | V4: 0 | W4: 15 | X4: 15 | Y4: 14 | Z4: 0 | AA4: 0 | AB4: 0 | AC4: 17 | AD4: 14 | AE4: 39 | AF4: 47 | AG4: 76 | AH4: 65 | AI4: 45 | AJ4: 49 | AK4: 36
A5: R3 | B5: 5 | C5: 4 | D5: 0 | E5: 0 | F5: 0 | G5: 16 | H5: 4 | I5: 11 | J5: 0 | K5: 0 | L5: 0 | M5: 0 | N5: 4 | O5: 0 | P5: 0 | Q5: 0 | R5: 0 | S5: 18 | T5: 0 | U5: 0 | V5: 0 | W5: 8 | X5: 2 | Y5: 0 | Z5: 0 | AA5: 0 | AB5: 0 | AC5: 1 | AD5: 0 | AE5: 0 | AF5: 0 | AG5: 0 | AH5: 0 | AI5: 0 | AJ5: 0 | AK5: 0
A6: tot_reg_act_per_matrix | B6: 23 | C6: 53 | D6: 48 | E6: 6 | F6: 12 | G6: 52 | H6: 48 | I6: 88 | J6: 48 | K6: 51 | L6: 49 | M6: 88 | N6: 95 | O6: 132 | P6: 97 | Q6: 70 | R6: 118 | S6: 117 | T6: 19 | U6: 11 | V6: 0 | W6: 95 | X6: 171 | Y6: 107 | Z6: 59 | AA6: 42 | AB6: 44 | AC6: 100 | AD6: 104 | AE6: 40 | AF6: 47 | AG6: 83 | AH6: 71 | AI6: 90 | AJ6: 77 | AK6: 77
A7: exp_tot_act_R0 | B7: 49
A8: exp_tot_act_R1 | B8: 1476
A9: exp_tot_act_R2 | B9: 834
A10: exp_tot_act_R3 | B10: 73
A11: exp_total_of_all_regions_activity | B11: 2432
A12: Total_number_of_frames: | B12: 1801
A13: Number_of_movement_frames: | B13: 1458
A14: Number_of_non-movement_frames: | B14: 343
A15: Inactivity_by_epoch: | B15: 34 | C15: 0 | D15: 2 | E15: 44 | F15: 40 | G15: 18 | H15: 7 | I15: 1 | J15: 4 | K15: 10 | L15: 1 | M15: 0 | N15: 0 | O15: 0 | P15: 0 | Q15: 2 | R15: 0 | S15: 0 | T15: 41 | U15: 39 | V15: 50 | W15: 8 | X15: 0 | Y15: 0 | Z15: 0 | AA15: 9 | AB15: 9 | AC15: 2 | AD15: 1 | AE15: 9 | AF15: 4 | AG15: 0 | AH15: 8 | AI15: 0 | AJ15: 0 | AK15: 0
A16: Total_number_of_VALID_frames: | B16: 1801
A17: Proportion_of_VALID_frames: | B17: 1
A18: Invalid_frame_count_(incorrect_or_too_many_contours): | B18: 0
A19: Proportion_of_Invalid_frames: | B19: 0
A20: Rejected_contour_count_outisde_regions: | B20: 0
A21: Rejected_contour_count_outisde_mask: | B21: 75
A22: Rejected_contour_count_too_small: | B22: 2687
A23: Rejected_contour_count_too_large: | B23: 2
A26: Video_File_Analysed | B26: IMG_0056_FA_UT_071222.mp4
A27: R0 | B27: 0 | C27: 0 | D27: 0 | E27: 0 | F27: 0 | G27: 0 | H27: 0 | I27: 3 | J27: 13 | K27: 7 | L27: 1 | M27: 2 | N27: 0 | O27: 0 | P27: 6 | Q27: 6 | R27: 0 | S27: 0 | T27: 0 | U27: 0 | V27: 0 | W27: 0 | X27: 0 | Y27: 0 | Z27: 0 | AA27: 0 | AB27: 0 | AC27: 0 | AD27: 0 | AE27: 0 | AF27: 0 | AG27: 0 | AH27: 0 | AI27: 0 | AJ27: 0 | AK27: 0
A28: R1 | B28: 78 | C28: 60 | D28: 33 | E28: 0 | F28: 47 | G28: 40 | H28: 102 | I28: 54 | J28: 54 | K28: 104 | L28: 45 | M28: 27 | N28: 21 | O28: 50 | P28: 62 | Q28: 62 | R28: 0 | S28: 0 | T28: 0 | U28: 0 | V28: 39 | W28: 44 | X28: 44 | Y28: 0 | Z28: 39 | AA28: 47 | AB28: 21 | AC28: 7 | AD28: 24 | AE28: 0 | AF28: 4 | AG28: 23 | AH28: 35 | AI28: 25 | AJ28: 7 | AK28: 0
A29: R2 | B29: 0 | C29: 0 | D29: 0 | E29: 0 | F29: 0 | G29: 0 | H29: 10 | I29: 62 | J29: 63 | K29: 38 | L29: 15 | M29: 13 | N29: 25 | O29: 16 | P29: 24 | Q29: 23 | R29: 9 | S29: 0 | T29: 11 | U29: 4 | V29: 61 | W29: 31 | X29: 45 | Y29: 0 | Z29: 3 | AA29: 0 | AB29: 0 | AC29: 27 | AD29: 9 | AE29: 0 | AF29: 0 | AG29: 0 | AH29: 19 | AI29: 22 | AJ29: 0 | AK29: 0
A30: R3 | B30: 0 | C30: 8 | D30: 0 | E30: 12 | F30: 0 | G30: 0 | H30: 0 | I30: 3 | J30: 6 | K30: 0 | L30: 0 | M30: 2 | N30: 4 | O30: 0 | P30: 4 | Q30: 7 | R30: 0 | S30: 0 | T30: 0 | U30: 0 | V30: 0 | W30: 9 | X30: 0 | Y30: 0 | Z30: 0 | AA30: 0 | AB30: 0 | AC30: 0 | AD30: 0 | AE30: 0 | AF30: 0 | AG30: 0 | AH30: 0 | AI30: 2 | AJ30: 0 | AK30: 0
A31: tot_reg_act_per_matrix | B31: 78 | C31: 68 | D31: 33 | E31: 12 | F31: 47 | G31: 40 | H31: 112 | I31: 122 | J31: 136 | K31: 149 | L31: 61 | M31: 44 | N31: 50 | O31: 66 | P31: 96 | Q31: 98 | R31: 9 | S31: 0 | T31: 11 | U31: 4 | V31: 100 | W31: 84 | X31: 89 | Y31: 0 | Z31: 42 | AA31: 47 | AB31: 21 | AC31: 34 | AD31: 33 | AE31: 0 | AF31: 4 | AG31: 23 | AH31: 54 | AI31: 49 | AJ31: 7 | AK31: 0
A32: exp_tot_act_R0 | B32: 38
A33: exp_tot_act_R1 | B33: 1198
A34: exp_tot_act_R2 | B34: 530
A35: exp_tot_act_R3 | B35: 57
A36: exp_total_of_all_regions_activity | B36: 1823
A37: Total_number_of_frames: | B37: 1801
A38: Number_of_movement_frames: | B38: 1131
A39: Number_of_non-movement_frames: | B39: 670
A40: Inactivity_by_epoch: | B40: 4 | C40: 3 | D40: 19 | E40: 38 | F40: 9 | G40: 24 | H40: 0 | I40: 0 | J40: 0 | K40: 0 | L40: 1 | M40: 5 | N40: 2 | O40: 22 | P40: 0 | Q40: 0 | R40: 43 | S40: 50 | T40: 39 | U40: 46 | V40: 0 | W40: 0 | X40: 10 | Y40: 50 | Z40: 10 | AA40: 2 | AB40: 31 | AC40: 26 | AD40: 19 | AE40: 50 | AF40: 46 | AG40: 25 | AH40: 0 | AI40: 1 | AJ40: 45 | AK40: 50
A41: Total_number_of_VALID_frames: | B41: 1801
A42: Proportion_of_VALID_frames: | B42: 1
...

Sheet B
A1: Video_File_Analysed | B1: IMG_0059_FA_P3_071222.mp4
A2: R0 | B2: 0 | C2: 0 | D2: 0 | E2: 2 | F2: 0 | G2: 0 | H2: 1 | I2: 4 | J2: 14 | K2: 8 | L2: 10 | M2: 0 | N2: 0 | O2: 1 | P2: 6 | Q2: 0 | R2: 0 | S2: 0 | T2: 3 | U2: 20 | V2: 1 | W2: 10 | X2: 4 | Y2: 3 | Z2: 0 | AA2: 0 | AB2: 0 | AC2: 0 | AD2: 0 | AE2: 0 | AF2: 10 | AG2: 11 | AH2: 0 | AI2: 7 | AJ2: 3 | AK2: 26
A3: R1 | B3: 12 | C3: 73 | D3: 87 | E3: 75 | F3: 117 | G3: 77 | H3: 112 | I3: 78 | J3: 65 | K3: 77 | L3: 112 | M3: 82 | N3: 58 | O3: 94 | P3: 91 | Q3: 94 | R3: 114 | S3: 69 | T3: 64 | U3: 147 | V3: 99 | W3: 114 | X3: 72 | Y3: 34 | Z3: 63 | AA3: 10 | AB3: 29 | AC3: 13 | AD3: 123 | AE3: 76 | AF3: 107 | AG3: 60 | AH3: 47 | AI3: 19 | AJ3: 66 | AK3: 36
A4: R2 | B4: 11 | C4: 15 | D4: 21 | E4: 15 | F4: 22 | G4: 11 | H4: 27 | I4: 15 | J4: 2 | K4: 5 | L4: 0 | M4: 7 | N4: 19 | O4: 21 | P4: 23 | Q4: 17 | R4: 32 | S4: 4 | T4: 45 | U4: 22 | V4: 37 | W4: 5 | X4: 0 | Y4: 63 | Z4: 47 | AA4: 23 | AB4: 56 | AC4: 29 | AD4: 6 | AE4: 8 | AF4: 5 | AG4: 0 | AH4: 9 | AI4: 30 | AJ4: 2 | AK4: 20
A5: R3 | B5: 0 | C5: 0 | D5: 0 | E5: 5 | F5: 4 | G5: 0 | H5: 5 | I5: 12 | J5: 1 | K5: 2 | L5: 0 | M5: 0 | N5: 9 | O5: 1 | P5: 4 | Q5: 9 | R5: 4 | S5: 0 | T5: 18 | U5: 3 | V5: 20 | W5: 0 | X5: 0 | Y5: 21 | Z5: 0 | AA5: 0 | AB5: 7 | AC5: 3 | AD5: 0 | AE5: 2 | AF5: 4 | AG5: 0 | AH5: 0 | AI5: 7 | AJ5: 29 | AK5: 47
A6: tot_reg_act_per_matrix | B6: 23 | C6: 88 | D6: 108 | E6: 97 | F6: 143 | G6: 88 | H6: 145 | I6: 109 | J6: 82 | K6: 92 | L6: 122 | M6: 89 | N6: 86 | O6: 117 | P6: 124 | Q6: 120 | R6: 150 | S6: 73 | T6: 130 | U6: 192 | V6: 157 | W6: 129 | X6: 76 | Y6: 121 | Z6: 110 | AA6: 33 | AB6: 92 | AC6: 45 | AD6: 129 | AE6: 86 | AF6: 126 | AG6: 71 | AH6: 56 | AI6: 63 | AJ6: 100 | AK6: 129
A7: exp_tot_act_R0 | B7: 144
A8: exp_tot_act_R1 | B8: 2666
A9: exp_tot_act_R2 | B9: 674
A10: exp_tot_act_R3 | B10: 217
A11: exp_total_of_all_regions_activity | B11: 3701
A12: Total_number_of_frames: | B12: 1801
A13: Number_of_movement_frames: | B13: 1669
A14: Number_of_non-movement_frames: | B14: 120
A15: Inactivity_by_epoch: | B15: 26 | C15: 1 | D15: 0 | E15: 1 | F15: 1 | G15: 2 | H15: 0 | I15: 0 | J15: 3 | K15: 3 | L15: 2 | M15: 1 | N15: 2 | O15: 2 | P15: 3 | Q15: 0 | R15: 0 | S15: 6 | T15: 0 | U15: 0 | V15: 0 | W15: 0 | X15: 0 | Y15: 0 | Z15: 0 | AA15: 34 | AB15: 3 | AC15: 5 | AD15: 0 | AE15: 4 | AF15: 0 | AG15: 1 | AH15: 8 | AI15: 11 | AJ15: 1 | AK15: 0
A16: Total_number_of_VALID_frames: | B16: 1789
A17: Proportion_of_VALID_frames: | B17: 0.99333704
A18: Invalid_frame_count_(incorrect_or_too_many_contours): | B18: 12
A19: Proportion_of_Invalid_frames: | B19: 0.006662965
A20: Rejected_contour_count_outisde_regions: | B20: 0
A21: Rejected_contour_count_outisde_mask: | B21: 28
A22: Rejected_contour_count_too_small: | B22: 3076
A23: Rejected_contour_count_too_large: | B23: 0
A26: Video_File_Analysed | B26: IMG_0060_FA_P3_071222.mp4
A27: R0 | B27: 0 | C27: 0 | D27: 4 | E27: 11 | F27: 14 | G27: 0 | H27: 0 | I27: 1 | J27: 3 | K27: 4 | L27: 3 | M27: 0 | N27: 7 | O27: 1 | P27: 7 | Q27: 0 | R27: 0 | S27: 6 | T27: 0 | U27: 6 | V27: 5 | W27: 0 | X27: 0 | Y27: 0 | Z27: 0 | AA27: 7 | AB27: 3 | AC27: 0 | AD27: 0 | AE27: 0 | AF27: 0 | AG27: 0 | AH27: 12 | AI27: 15 | AJ27: 0 | AK27: 0
A28: R1 | B28: 128 | C28: 89 | D28: 73 | E28: 63 | F28: 123 | G28: 50 | H28: 77 | I28: 112 | J28: 54 | K28: 60 | L28: 84 | M28: 117 | N28: 54 | O28: 71 | P28: 94 | Q28: 62 | R28: 66 | S28: 58 | T28: 79 | U28: 45 | V28: 71 | W28: 105 | X28: 82 | Y28: 88 | Z28: 39 | AA28: 109 | AB28: 155 | AC28: 13 | AD28: 83 | AE28: 73 | AF28: 72 | AG28: 50 | AH28: 26 | AI28: 19 | AJ28: 45 | AK28: 101
A29: R2 | B29: 5 | C29: 15 | D29: 22 | E29: 27 | F29: 33 | G29: 69 | H29: 17 | I29: 25 | J29: 65 | K29: 51 | L29: 19 | M29: 43 | N29: 36 | O29: 59 | P29: 62 | Q29: 46 | R29: 26 | S29: 46 | T29: 48 | U29: 20 | V29: 34 | W29: 10 | X29: 7 | Y29: 21 | Z29: 21 | AA29: 42 | AB29: 15 | AC29: 5 | AD29: 8 | AE29: 33 | AF29: 2 | AG29: 0 | AH29: 2 | AI29: 0 | AJ29: 0 | AK29: 6
A30: R3 | B30: 4 | C30: 4 | D30: 5 | E30: 8 | F30: 3 | G30: 11 | H30: 5 | I30: 5 | J30: 18 | K30: 22 | L30: 30 | M30: 7 | N30: 25 | O30: 44 | P30: 19 | Q30: 51 | R30: 9 | S30: 27 | T30: 33 | U30: 41 | V30: 28 | W30: 16 | X30: 52 | Y30: 32 | Z30: 22 | AA30: 4 | AB30: 8 | AC30: 26 | AD30: 0 | AE30: 42 | AF30: 28 | AG30: 0 | AH30: 0 | AI30: 0 | AJ30: 0 | AK30: 6
A31: tot_reg_act_per_matrix | B31: 137 | C31: 108 | D31: 104 | E31: 109 | F31: 173 | G31: 130 | H31: 99 | I31: 143 | J31: 140 | K31: 137 | L31: 136 | M31: 167 | N31: 122 | O31: 175 | P31: 182 | Q31: 159 | R31: 101 | S31: 137 | T31: 160 | U31: 112 | V31: 138 | W31: 131 | X31: 141 | Y31: 141 | Z31: 82 | AA31: 162 | AB31: 181 | AC31: 44 | AD31: 91 | AE31: 148 | AF31: 102 | AG31: 50 | AH31: 40 | AI31: 34 | AJ31: 45 | AK31: 113
A32: exp_tot_act_R0 | B32: 109
A33: exp_tot_act_R1 | B33: 2690
A34: exp_tot_act_R2 | B34: 940
A35: exp_tot_act_R3 | B35: 635
A36: exp_total_of_all_regions_activity | B36: 4374
A37: Total_number_of_frames: | B37: 1801
A38: Number_of_movement_frames: | B38: 1680
A39: Number_of_non-movement_frames: | B39: 88
A40: Inactivity_by_epoch: | B40: 5 | C40: 0 | D40: 3 | E40: 1 | F40: 0 | G40: 0 | H40: 0 | I40: 0 | J40: 0 | K40: 0 | L40: 1 | M40: 0 | N40: 0 | O40: 0 | P40: 0 | Q40: 0 | R40: 0 | S40: 0 | T40: 1 | U40: 0 | V40: 0 | W40: 0 | X40: 1 | Y40: 0 | Z40: 6 | AA40: 0 | AB40: 0 | AC40: 12 | AD40: 3 | AE40: 0 | AF40: 0 | AG40: 0 | AH40: 11 | AI40: 17 | AJ40: 27 | AK40: 0
A41: Total_number_of_VALID_frames: | B41: 1768
A42: Proportion_of_VALID_frames: | B42: 0.9816768
...

Sheet C
A1: Video_File_Analysed | B1: IMG_0062_FA_OSP_071222.mp4
A2: R0 | B2: 0 | C2: 0 | D2: 0 | E2: 1 | F2: 0 | G2: 1 | H2: 0 | I2: 11 | J2: 0 | K2: 0 | L2: 0 | M2: 0 | N2: 0 | O2: 0 | P2: 2 | Q2: 0 | R2: 0 | S2: 1 | T2: 0 | U2: 0 | V2: 0 | W2: 0 | X2: 0 | Y2: 0 | Z2: 0 | AA2: 0 | AB2: 0 | AC2: 0 | AD2: 0 | AE2: 0 | AF2: 0 | AG2: 0 | AH2: 0 | AI2: 7 | AJ2: 2 | AK2: 0
A3: R1 | B3: 89 | C3: 80 | D3: 121 | E3: 121 | F3: 65 | G3: 81 | H3: 12 | I3: 48 | J3: 14 | K3: 32 | L3: 9 | M3: 25 | N3: 0 | O3: 16 | P3: 100 | Q3: 70 | R3: 2 | S3: 97 | T3: 104 | U3: 48 | V3: 0 | W3: 7 | X3: 21 | Y3: 14 | Z3: 0 | AA3: 0 | AB3: 17 | AC3: 11 | AD3: 0 | AE3: 78 | AF3: 89 | AG3: 20 | AH3: 29 | AI3: 6 | AJ3: 48 | AK3: 56
A4: R2 | B4: 17 | C4: 31 | D4: 17 | E4: 10 | F4: 12 | G4: 23 | H4: 34 | I4: 15 | J4: 30 | K4: 44 | L4: 2 | M4: 3 | N4: 0 | O4: 0 | P4: 19 | Q4: 15 | R4: 0 | S4: 10 | T4: 0 | U4: 17 | V4: 0 | W4: 1 | X4: 0 | Y4: 0 | Z4: 0 | AA4: 0 | AB4: 0 | AC4: 0 | AD4: 0 | AE4: 1 | AF4: 0 | AG4: 0 | AH4: 0 | AI4: 14 | AJ4: 0 | AK4: 0
A5: R3 | B5: 10 | C5: 6 | D5: 9 | E5: 0 | F5: 0 | G5: 0 | H5: 17 | I5: 10 | J5: 14 | K5: 18 | L5: 0 | M5: 0 | N5: 0 | O5: 0 | P5: 17 | Q5: 0 | R5: 0 | S5: 6 | T5: 0 | U5: 1 | V5: 0 | W5: 0 | X5: 0 | Y5: 0 | Z5: 0 | AA5: 0 | AB5: 0 | AC5: 0 | AD5: 0 | AE5: 0 | AF5: 0 | AG5: 0 | AH5: 0 | AI5: 16 | AJ5: 0 | AK5: 0
A6: tot_reg_act_per_matrix | B6: 116 | C6: 117 | D6: 147 | E6: 132 | F6: 77 | G6: 105 | H6: 63 | I6: 84 | J6: 58 | K6: 94 | L6: 11 | M6: 28 | N6: 0 | O6: 16 | P6: 138 | Q6: 85 | R6: 2 | S6: 114 | T6: 104 | U6: 66 | V6: 0 | W6: 8 | X6: 21 | Y6: 14 | Z6: 0 | AA6: 0 | AB6: 17 | AC6: 11 | AD6: 0 | AE6: 79 | AF6: 89 | AG6: 20 | AH6: 29 | AI6: 43 | AJ6: 50 | AK6: 56
A7: exp_tot_act_R0 | B7: 25
A8: exp_tot_act_R1 | B8: 1530
A9: exp_tot_act_R2 | B9: 315
A10: exp_tot_act_R3 | B10: 124
A11: exp_total_of_all_regions_activity | B11: 1994
A12: Total_number_of_frames: | B12: 1801
A13: Number_of_movement_frames: | B13: 1070
A14: Number_of_non-movement_frames: | B14: 731
A15: Inactivity_by_epoch: | B15: 5 | C15: 0 | D15: 1 | E15: 0 | F15: 0 | G15: 0 | H15: 3 | I15: 0 | J15: 4 | K15: 8 | L15: 41 | M15: 27 | N15: 50 | O15: 38 | P15: 3 | Q15: 12 | R15: 46 | S15: 0 | T15: 1 | U15: 17 | V15: 50 | W15: 40 | X15: 31 | Y15: 36 | Z15: 50 | AA15: 50 | AB15: 33 | AC15: 39 | AD15: 50 | AE15: 1 | AF15: 0 | AG15: 35 | AH15: 30 | AI15: 9 | AJ15: 10 | AK15: 11
A16: Total_number_of_VALID_frames: | B16: 1801
A17: Proportion_of_VALID_frames: | B17: 1
A18: Invalid_frame_count_(incorrect_or_too_many_contours): | B18: 0
A19: Proportion_of_Invalid_frames: | B19: 0
A20: Rejected_contour_count_outisde_regions: | B20: 0
A21: Rejected_contour_count_outisde_mask: | B21: 12
A22: Rejected_contour_count_too_small: | B22: 2106
A23: Rejected_contour_count_too_large: | B23: 0
A26: Video_File_Analysed | B26: IMG_0063_FA_OSP_071222.mp4
A27: R0 | B27: 0 | C27: 2 | D27: 3 | E27: 11 | F27: 0 | G27: 3 | H27: 0 | I27: 0 | J27: 0 | K27: 0 | L27: 0 | M27: 0 | N27: 0 | O27: 0 | P27: 0 | Q27: 2 | R27: 1 | S27: 0 | T27: 0 | U27: 0 | V27: 0 | W27: 0 | X27: 0 | Y27: 0 | Z27: 0 | AA27: 0 | AB27: 0 | AC27: 10 | AD27: 4 | AE27: 0 | AF27: 0 | AG27: 0 | AH27: 0 | AI27: 0 | AJ27: 0 | AK27: 0
A28: R1 | B28: 58 | C28: 101 | D28: 117 | E28: 110 | F28: 71 | G28: 38 | H28: 44 | I28: 55 | J28: 42 | K28: 30 | L28: 33 | M28: 95 | N28: 55 | O28: 28 | P28: 58 | Q28: 17 | R28: 32 | S28: 2 | T28: 0 | U28: 0 | V28: 0 | W28: 0 | X28: 0 | Y28: 11 | Z28: 0 | AA28: 25 | AB28: 21 | AC28: 55 | AD28: 127 | AE28: 85 | AF28: 16 | AG28: 76 | AH28: 82 | AI28: 7 | AJ28: 0 | AK28: 10
A29: R2 | B29: 22 | C29: 23 | D29: 40 | E29: 12 | F29: 0 | G29: 67 | H29: 58 | I29: 22 | J29: 33 | K29: 14 | L29: 66 | M29: 44 | N29: 0 | O29: 6 | P29: 29 | Q29: 19 | R29: 6 | S29: 0 | T29: 0 | U29: 0 | V29: 0 | W29: 0 | X29: 0 | Y29: 0 | Z29: 0 | AA29: 0 | AB29: 0 | AC29: 0 | AD29: 0 | AE29: 0 | AF29: 0 | AG29: 0 | AH29: 0 | AI29: 0 | AJ29: 0 | AK29: 0
A30: R3 | B30: 5 | C30: 20 | D30: 15 | E30: 18 | F30: 0 | G30: 0 | H30: 11 | I30: 42 | J30: 11 | K30: 26 | L30: 6 | M30: 0 | N30: 0 | O30: 0 | P30: 14 | Q30: 3 | R30: 0 | S30: 0 | T30: 0 | U30: 0 | V30: 0 | W30: 0 | X30: 0 | Y30: 0 | Z30: 0 | AA30: 0 | AB30: 0 | AC30: 0 | AD30: 0 | AE30: 0 | AF30: 0 | AG30: 0 | AH30: 0 | AI30: 0 | AJ30: 0 | AK30: 0
A31: tot_reg_act_per_matrix | B31: 85 | C31: 146 | D31: 175 | E31: 151 | F31: 71 | G31: 108 | H31: 113 | I31: 119 | J31: 86 | K31: 70 | L31: 105 | M31: 139 | N31: 55 | O31: 34 | P31: 101 | Q31: 41 | R31: 39 | S31: 2 | T31: 0 | U31: 0 | V31: 0 | W31: 0 | X31: 0 | Y31: 11 | Z31: 0 | AA31: 25 | AB31: 21 | AC31: 65 | AD31: 131 | AE31: 85 | AF31: 16 | AG31: 76 | AH31: 82 | AI31: 7 | AJ31: 0 | AK31: 10
A32: exp_tot_act_R0 | B32: 36
A33: exp_tot_act_R1 | B33: 1501
A34: exp_tot_act_R2 | B34: 461
A35: exp_tot_act_R3 | B35: 171
A36: exp_total_of_all_regions_activity | B36: 2169
A37: Total_number_of_frames: | B37: 1801
A38: Number_of_movement_frames: | B38: 1082
A39: Number_of_non-movement_frames: | B39: 717
A40: Inactivity_by_epoch: | B40: 13 | C40: 0 | D40: 0 | E40: 0 | F40: 6 | G40: 0 | H40: 0 | I40: 0 | J40: 0 | K40: 0 | L40: 6 | M40: 0 | N40: 11 | O40: 27 | P40: 0 | Q40: 9 | R40: 14 | S40: 48 | T40: 50 | U40: 50 | V40: 50 | W40: 50 | X40: 50 | Y40: 39 | Z40: 50 | AA40: 23 | AB40: 30 | AC40: 2 | AD40: 0 | AE40: 4 | AF40: 38 | AG40: 3 | AH40: 9 | AI40: 43 | AJ40: 50 | AK40: 42
A41: Total_number_of_VALID_frames: | B41: 1799
A42: Proportion_of_VALID_frames: | B42: 0.9988895
...

Sheet D

Sheet E
A1: Video_File_Analysed | B1: IMG_0046_FU_UT_051222.mp4
A2: R0 | B2: 0 | C2: 0 | D2: 10 | E2: 0 | F2: 0 | G2: 1 | H2: 0 | I2: 0 | J2: 0 | K2: 4 | L2: 0 | M2: 16 | N2: 3 | O2: 1 | P2: 0 | Q2: 0 | R2: 16 | S2: 5 | T2: 6 | U2: 2 | V2: 1 | W2: 1 | X2: 6 | Y2: 2 | Z2: 0 | AA2: 0 | AB2: 0 | AC2: 11 | AD2: 0 | AE2: 0 | AF2: 0 | AG2: 0 | AH2: 0 | AI2: 0 | AJ2: 0 | AK2: 0
A3: R1 | B3: 42 | C3: 0 | D3: 33 | E3: 39 | F3: 83 | G3: 63 | H3: 22 | I3: 33 | J3: 34 | K3: 36 | L3: 38 | M3: 3 | N3: 32 | O3: 17 | P3: 23 | Q3: 24 | R3: 48 | S3: 33 | T3: 5 | U3: 19 | V3: 36 | W3: 41 | X3: 12 | Y3: 76 | Z3: 44 | AA3: 2 | AB3: 68 | AC3: 22 | AD3: 0 | AE3: 0 | AF3: 30 | AG3: 0 | AH3: 13 | AI3: 69 | AJ3: 0 | AK3: 0
A4: R2 | B4: 0 | C4: 0 | D4: 0 | E4: 18 | F4: 22 | G4: 58 | H4: 9 | I4: 41 | J4: 31 | K4: 39 | L4: 18 | M4: 22 | N4: 4 | O4: 22 | P4: 73 | Q4: 40 | R4: 0 | S4: 0 | T4: 12 | U4: 19 | V4: 22 | W4: 8 | X4: 11 | Y4: 11 | Z4: 12 | AA4: 63 | AB4: 20 | AC4: 7 | AD4: 0 | AE4: 0 | AF4: 25 | AG4: 4 | AH4: 18 | AI4: 27 | AJ4: 0 | AK4: 0
A5: R3 | B5: 8 | C5: 0 | D5: 21 | E5: 5 | F5: 0 | G5: 14 | H5: 10 | I5: 1 | J5: 0 | K5: 2 | L5: 5 | M5: 21 | N5: 0 | O5: 0 | P5: 0 | Q5: 21 | R5: 0 | S5: 0 | T5: 0 | U5: 2 | V5: 1 | W5: 0 | X5: 0 | Y5: 3 | Z5: 0 | AA5: 24 | AB5: 3 | AC5: 19 | AD5: 3 | AE5: 0 | AF5: 2 | AG5: 0 | AH5: 16 | AI5: 0 | AJ5: 0 | AK5: 0
A6: tot_reg_act_per_matrix | B6: 50 | C6: 0 | D6: 64 | E6: 62 | F6: 105 | G6: 136 | H6: 41 | I6: 75 | J6: 65 | K6: 81 | L6: 61 | M6: 62 | N6: 39 | O6: 40 | P6: 96 | Q6: 85 | R6: 64 | S6: 38 | T6: 23 | U6: 42 | V6: 60 | W6: 50 | X6: 29 | Y6: 92 | Z6: 56 | AA6: 89 | AB6: 91 | AC6: 59 | AD6: 3 | AE6: 0 | AF6: 57 | AG6: 4 | AH6: 47 | AI6: 96 | AJ6: 0 | AK6: 0
A7: exp_tot_act_R0 | B7: 85
A8: exp_tot_act_R1 | B8: 1040
A9: exp_tot_act_R2 | B9: 656
A10: exp_tot_act_R3 | B10: 181
A11: exp_total_of_all_regions_activity | B11: 1962
A12: Total_number_of_frames: | B12: 1801
A13: Number_of_movement_frames: | B13: 1250
A14: Number_of_non-movement_frames: | B14: 550
A15: Inactivity_by_epoch: | B15: 7 | C15: 50 | D15: 13 | E15: 3 | F15: 2 | G15: 0 | H15: 19 | I15: 3 | J15: 6 | K15: 1 | L15: 19 | M15: 13 | N15: 11 | O15: 9 | P15: 0 | Q15: 8 | R15: 0 | S15: 12 | T15: 35 | U15: 10 | V15: 3 | W15: 13 | X15: 37 | Y15: 1 | Z15: 0 | AA15: 3 | AB15: 0 | AC15: 3 | AD15: 49 | AE15: 50 | AF15: 4 | AG15: 48 | AH15: 16 | AI15: 2 | AJ15: 50 | AK15: 50
A16: Total_number_of_VALID_frames: | B16: 1800
A17: Proportion_of_VALID_frames: | B17: 0.9994447
A18: Invalid_frame_count_(incorrect_or_too_many_contours): | B18: 1
A19: Proportion_of_Invalid_frames: | B19: 0.00055524707
A20: Rejected_contour_count_outisde_regions: | B20: 0
A21: Rejected_contour_count_outisde_mask: | B21: 245
A22: Rejected_contour_count_too_small: | B22: 2688
A23: Rejected_contour_count_too_large: | B23: 6
A26: Video_File_Analysed | B26: IMG_0047_FU_UT_051222.mp4
A27: R0 | B27: 1 | C27: 0 | D27: 0 | E27: 0 | F27: 1 | G27: 0 | H27: 2 | I27: 0 | J27: 0 | K27: 3 | L27: 2 | M27: 0 | N27: 0 | O27: 1 | P27: 0 | Q27: 0 | R27: 0 | S27: 0 | T27: 0 | U27: 0 | V27: 3 | W27: 0 | X27: 0 | Y27: 0 | Z27: 2 | AA27: 5 | AB27: 0 | AC27: 0 | AD27: 0 | AE27: 0 | AF27: 0 | AG27: 0 | AH27: 0 | AI27: 0 | AJ27: 0 | AK27: 0
A28: R1 | B28: 55 | C28: 32 | D28: 36 | E28: 23 | F28: 29 | G28: 23 | H28: 41 | I28: 47 | J28: 38 | K28: 64 | L28: 57 | M28: 7 | N28: 0 | O28: 12 | P28: 4 | Q28: 37 | R28: 16 | S28: 0 | T28: 3 | U28: 45 | V28: 74 | W28: 12 | X28: 5 | Y28: 47 | Z28: 77 | AA28: 31 | AB28: 0 | AC28: 6 | AD28: 18 | AE28: 0 | AF28: 31 | AG28: 14 | AH28: 0 | AI28: 0 | AJ28: 0 | AK28: 0
A29: R2 | B29: 5 | C29: 0 | D29: 0 | E29: 14 | F29: 23 | G29: 38 | H29: 50 | I29: 54 | J29: 25 | K29: 47 | L29: 34 | M29: 0 | N29: 0 | O29: 21 | P29: 16 | Q29: 18 | R29: 0 | S29: 0 | T29: 0 | U29: 11 | V29: 16 | W29: 0 | X29: 0 | Y29: 7 | Z29: 25 | AA29: 32 | AB29: 5 | AC29: 12 | AD29: 0 | AE29: 0 | AF29: 0 | AG29: 20 | AH29: 0 | AI29: 0 | AJ29: 0 | AK29: 1
A30: R3 | B30: 1 | C30: 0 | D30: 0 | E30: 0 | F30: 2 | G30: 0 | H30: 5 | I30: 2 | J30: 0 | K30: 9 | L30: 2 | M30: 0 | N30: 0 | O30: 1 | P30: 0 | Q30: 0 | R30: 0 | S30: 0 | T30: 0 | U30: 1 | V30: 2 | W30: 0 | X30: 0 | Y30: 0 | Z30: 11 | AA30: 0 | AB30: 0 | AC30: 0 | AD30: 0 | AE30: 0 | AF30: 0 | AG30: 0 | AH30: 1 | AI30: 0 | AJ30: 0 | AK30: 0
A31: tot_reg_act_per_matrix | B31: 62 | C31: 32 | D31: 36 | E31: 37 | F31: 55 | G31: 61 | H31: 98 | I31: 103 | J31: 63 | K31: 123 | L31: 95 | M31: 7 | N31: 0 | O31: 35 | P31: 20 | Q31: 55 | R31: 16 | S31: 0 | T31: 3 | U31: 57 | V31: 95 | W31: 12 | X31: 5 | Y31: 54 | Z31: 115 | AA31: 68 | AB31: 5 | AC31: 18 | AD31: 18 | AE31: 0 | AF31: 31 | AG31: 34 | AH31: 1 | AI31: 0 | AJ31: 0 | AK31: 1
A32: exp_tot_act_R0 | B32: 20
A33: exp_tot_act_R1 | B33: 884
A34: exp_tot_act_R2 | B34: 474
A35: exp_tot_act_R3 | B35: 37
A36: exp_total_of_all_regions_activity | B36: 1415
A37: Total_number_of_frames: | B37: 1801
A38: Number_of_movement_frames: | B38: 901
A39: Number_of_non-movement_frames: | B39: 900
A40: Inactivity_by_epoch: | B40: 9 | C40: 20 | D40: 12 | E40: 26 | F40: 5 | G40: 12 | H40: 0 | I40: 12 | J40: 11 | K40: 1 | L40: 0 | M40: 45 | N40: 50 | O40: 24 | P40: 32 | Q40: 5 | R40: 36 | S40: 50 | T40: 46 | U40: 1 | V40: 1 | W40: 40 | X40: 45 | Y40: 2 | Z40: 0 | AA40: 0 | AB40: 47 | AC40: 37 | AD40: 34 | AE40: 50 | AF40: 31 | AG40: 18 | AH40: 49 | AI40: 50 | AJ40: 50 | AK40: 49
A41: Total_number_of_VALID_frames: | B41: 1801
A42: Proportion_of_VALID_frames: | B42: 1
...

Sheet F
A1: Video_File_Analysed | B1: IMG_0049_FU_P3_051222.mp4
A2: R0 | B2: 0 | C2: 0 | D2: 0 | E2: 0 | F2: 0 | G2: 0 | H2: 0 | I2: 0 | J2: 2 | K2: 2 | L2: 2 | M2: 4 | N2: 3 | O2: 3 | P2: 1 | Q2: 0 | R2: 7 | S2: 9 | T2: 0 | U2: 0 | V2: 2 | W2: 2 | X2: 1 | Y2: 0 | Z2: 5 | AA2: 3 | AB2: 0 | AC2: 4 | AD2: 1 | AE2: 1 | AF2: 0 | AG2: 3 | AH2: 0 | AI2: 4 | AJ2: 0 | AK2: 4
A3: R1 | B3: 0 | C3: 0 | D3: 52 | E3: 46 | F3: 42 | G3: 32 | H3: 39 | I3: 57 | J3: 17 | K3: 31 | L3: 49 | M3: 102 | N3: 51 | O3: 27 | P3: 35 | Q3: 16 | R3: 38 | S3: 112 | T3: 36 | U3: 36 | V3: 44 | W3: 42 | X3: 66 | Y3: 63 | Z3: 80 | AA3: 82 | AB3: 42 | AC3: 42 | AD3: 52 | AE3: 46 | AF3: 48 | AG3: 47 | AH3: 42 | AI3: 77 | AJ3: 52 | AK3: 90
A4: R2 | B4: 3 | C4: 11 | D4: 0 | E4: 4 | F4: 2 | G4: 1 | H4: 25 | I4: 41 | J4: 35 | K4: 13 | L4: 55 | M4: 51 | N4: 55 | O4: 51 | P4: 17 | Q4: 35 | R4: 53 | S4: 18 | T4: 41 | U4: 6 | V4: 25 | W4: 29 | X4: 37 | Y4: 23 | Z4: 72 | AA4: 41 | AB4: 43 | AC4: 32 | AD4: 13 | AE4: 33 | AF4: 31 | AG4: 44 | AH4: 52 | AI4: 50 | AJ4: 78 | AK4: 43
A5: R3 | B5: 0 | C5: 0 | D5: 0 | E5: 0 | F5: 0 | G5: 0 | H5: 0 | I5: 3 | J5: 1 | K5: 1 | L5: 7 | M5: 20 | N5: 6 | O5: 6 | P5: 2 | Q5: 0 | R5: 9 | S5: 5 | T5: 6 | U5: 0 | V5: 11 | W5: 2 | X5: 5 | Y5: 35 | Z5: 18 | AA5: 6 | AB5: 5 | AC5: 0 | AD5: 2 | AE5: 2 | AF5: 3 | AG5: 7 | AH5: 1 | AI5: 14 | AJ5: 2 | AK5: 11
A6: tot_reg_act_per_matrix | B6: 3 | C6: 11 | D6: 52 | E6: 50 | F6: 44 | G6: 33 | H6: 64 | I6: 101 | J6: 55 | K6: 47 | L6: 113 | M6: 177 | N6: 115 | O6: 87 | P6: 55 | Q6: 51 | R6: 107 | S6: 144 | T6: 83 | U6: 42 | V6: 82 | W6: 75 | X6: 109 | Y6: 121 | Z6: 175 | AA6: 132 | AB6: 90 | AC6: 78 | AD6: 68 | AE6: 82 | AF6: 82 | AG6: 101 | AH6: 95 | AI6: 145 | AJ6: 132 | AK6: 148
A7: exp_tot_act_R0 | B7: 63
A8: exp_tot_act_R1 | B8: 1733
A9: exp_tot_act_R2 | B9: 1163
A10: exp_tot_act_R3 | B10: 190
A11: exp_total_of_all_regions_activity | B11: 3149
A12: Total_number_of_frames: | B12: 1801
A13: Number_of_movement_frames: | B13: 1544
A14: Number_of_non-movement_frames: | B14: 246
A15: Inactivity_by_epoch: | B15: 46 | C15: 41 | D15: 5 | E15: 11 | F15: 20 | G15: 26 | H15: 7 | I15: 3 | J15: 7 | K15: 6 | L15: 1 | M15: 0 | N15: 2 | O15: 2 | P15: 9 | Q15: 16 | R15: 6 | S15: 0 | T15: 0 | U15: 10 | V15: 13 | W15: 4 | X15: 0 | Y15: 0 | Z15: 0 | AA15: 0 | AB15: 1 | AC15: 3 | AD15: 3 | AE15: 2 | AF15: 1 | AG15: 0 | AH15: 1 | AI15: 0 | AJ15: 0 | AK15: 0
A16: Total_number_of_VALID_frames: | B16: 1790
A17: Proportion_of_VALID_frames: | B17: 0.99389225
A18: Invalid_frame_count_(incorrect_or_too_many_contours): | B18: 11
A19: Proportion_of_Invalid_frames: | B19: 0.0061077178
A20: Rejected_contour_count_outisde_regions: | B20: 0
A21: Rejected_contour_count_outisde_mask: | B21: 37
A22: Rejected_contour_count_too_small: | B22: 2532
A23: Rejected_contour_count_too_large: | B23: 2
A26: Video_File_Analysed | B26: IMG_0050_FU_P3_051222.mp4
A27: R0 | B27: 3 | C27: 1 | D27: 0 | E27: 2 | F27: 0 | G27: 1 | H27: 2 | I27: 5 | J27: 2 | K27: 1 | L27: 2 | M27: 1 | N27: 4 | O27: 4 | P27: 1 | Q27: 10 | R27: 5 | S27: 7 | T27: 3 | U27: 3 | V27: 4 | W27: 5 | X27: 12 | Y27: 1 | Z27: 3 | AA27: 0 | AB27: 5 | AC27: 0 | AD27: 0 | AE27: 2 | AF27: 0 | AG27: 2 | AH27: 1 | AI27: 5 | AJ27: 10 | AK27: 5
A28: R1 | B28: 20 | C28: 61 | D28: 34 | E28: 55 | F28: 48 | G28: 58 | H28: 83 | I28: 75 | J28: 34 | K28: 30 | L28: 47 | M28: 59 | N28: 102 | O28: 76 | P28: 80 | Q28: 52 | R28: 83 | S28: 99 | T28: 98 | U28: 61 | V28: 39 | W28: 72 | X28: 37 | Y28: 51 | Z28: 80 | AA28: 107 | AB28: 60 | AC28: 84 | AD28: 101 | AE28: 58 | AF28: 47 | AG28: 36 | AH28: 63 | AI28: 49 | AJ28: 68 | AK28: 68
A29: R2 | B29: 11 | C29: 13 | D29: 22 | E29: 33 | F29: 28 | G29: 42 | H29: 41 | I29: 50 | J29: 15 | K29: 37 | L29: 69 | M29: 75 | N29: 56 | O29: 77 | P29: 57 | Q29: 58 | R29: 88 | S29: 91 | T29: 63 | U29: 103 | V29: 78 | W29: 39 | X29: 38 | Y29: 31 | Z29: 37 | AA29: 46 | AB29: 64 | AC29: 65 | AD29: 31 | AE29: 60 | AF29: 42 | AG29: 49 | AH29: 92 | AI29: 85 | AJ29: 54 | AK29: 68
A30: R3 | B30: 2 | C30: 2 | D30: 5 | E30: 1 | F30: 4 | G30: 22 | H30: 7 | I30: 19 | J30: 39 | K30: 23 | L30: 14 | M30: 25 | N30: 13 | O30: 12 | P30: 13 | Q30: 5 | R30: 14 | S30: 16 | T30: 11 | U30: 7 | V30: 17 | W30: 9 | X30: 3 | Y30: 2 | Z30: 11 | AA30: 3 | AB30: 2 | AC30: 12 | AD30: 10 | AE30: 10 | AF30: 9 | AG30: 9 | AH30: 8 | AI30: 9 | AJ30: 6 | AK30: 1
A31: tot_reg_act_per_matrix | B31: 36 | C31: 77 | D31: 61 | E31: 91 | F31: 80 | G31: 123 | H31: 133 | I31: 149 | J31: 90 | K31: 91 | L31: 132 | M31: 160 | N31: 175 | O31: 169 | P31: 151 | Q31: 125 | R31: 190 | S31: 213 | T31: 175 | U31: 174 | V31: 138 | W31: 125 | X31: 90 | Y31: 85 | Z31: 131 | AA31: 156 | AB31: 131 | AC31: 161 | AD31: 142 | AE31: 130 | AF31: 98 | AG31: 96 | AH31: 164 | AI31: 148 | AJ31: 138 | AK31: 142
A32: exp_tot_act_R0 | B32: 112
A33: exp_tot_act_R1 | B33: 2275
A34: exp_tot_act_R2 | B34: 1908
A35: exp_tot_act_R3 | B35: 375
A36: exp_total_of_all_regions_activity | B36: 4670
A37: Total_number_of_frames: | B37: 1801
A38: Number_of_movement_frames: | B38: 1739
A39: Number_of_non-movement_frames: | B39: 32
A40: Inactivity_by_epoch: | B40: 13 | C40: 6 | D40: 1 | E40: 5 | F40: 2 | G40: 0 | H40: 0 | I40: 0 | J40: 2 | K40: 0 | L40: 0 | M40: 1 | N40: 0 | O40: 0 | P40: 0 | Q40: 0 | R40: 0 | S40: 0 | T40: 0 | U40: 0 | V40: 0 | W40: 0 | X40: 1 | Y40: 1 | Z40: 0 | AA40: 0 | AB40: 0 | AC40: 0 | AD40: 0 | AE40: 0 | AF40: 0 | AG40: 0 | AH40: 0 | AI40: 0 | AJ40: 0 | AK40: 0
A41: Total_number_of_VALID_frames: | B41: 1771
A42: Proportion_of_VALID_frames: | B42: 0.9833426
...

Sheet G
A1: Video_File_Analysed | B1: IMG_0052_FU_OSP_051222.mp4
A2: R0 | B2: 22 | C2: 6 | D2: 6 | E2: 11 | F2: 18 | G2: 2 | H2: 9 | I2: 4 | J2: 6 | K2: 8 | L2: 0 | M2: 0 | N2: 2 | O2: 0 | P2: 5 | Q2: 0 | R2: 0 | S2: 0 | T2: 0 | U2: 0 | V2: 17 | W2: 0 | X2: 0 | Y2: 0 | Z2: 0 | AA2: 0 | AB2: 5 | AC2: 0 | AD2: 0 | AE2: 0 | AF2: 0 | AG2: 0 | AH2: 0 | AI2: 0 | AJ2: 0 | AK2: 0
A3: R1 | B3: 67 | C3: 79 | D3: 86 | E3: 76 | F3: 84 | G3: 58 | H3: 93 | I3: 74 | J3: 36 | K3: 48 | L3: 21 | M3: 83 | N3: 91 | O3: 69 | P3: 53 | Q3: 56 | R3: 85 | S3: 107 | T3: 107 | U3: 29 | V3: 107 | W3: 47 | X3: 0 | Y3: 0 | Z3: 47 | AA3: 60 | AB3: 48 | AC3: 38 | AD3: 69 | AE3: 86 | AF3: 26 | AG3: 23 | AH3: 91 | AI3: 35 | AJ3: 21 | AK3: 84
A4: R2 | B4: 31 | C4: 30 | D4: 45 | E4: 56 | F4: 87 | G4: 28 | H4: 42 | I4: 14 | J4: 54 | K4: 48 | L4: 72 | M4: 15 | N4: 27 | O4: 16 | P4: 56 | Q4: 41 | R4: 1 | S4: 12 | T4: 4 | U4: 7 | V4: 25 | W4: 30 | X4: 0 | Y4: 21 | Z4: 49 | AA4: 51 | AB4: 33 | AC4: 17 | AD4: 21 | AE4: 27 | AF4: 2 | AG4: 0 | AH4: 41 | AI4: 46 | AJ4: 24 | AK4: 11
A5: R3 | B5: 0 | C5: 0 | D5: 20 | E5: 7 | F5: 3 | G5: 3 | H5: 11 | I5: 26 | J5: 43 | K5: 32 | L5: 70 | M5: 4 | N5: 22 | O5: 49 | P5: 0 | Q5: 0 | R5: 0 | S5: 0 | T5: 0 | U5: 16 | V5: 14 | W5: 33 | X5: 5 | Y5: 3 | Z5: 3 | AA5: 0 | AB5: 0 | AC5: 3 | AD5: 0 | AE5: 1 | AF5: 20 | AG5: 40 | AH5: 22 | AI5: 9 | AJ5: 0 | AK5: 6
A6: tot_reg_act_per_matrix | B6: 120 | C6: 115 | D6: 157 | E6: 150 | F6: 192 | G6: 91 | H6: 155 | I6: 118 | J6: 139 | K6: 136 | L6: 163 | M6: 102 | N6: 142 | O6: 134 | P6: 114 | Q6: 97 | R6: 86 | S6: 119 | T6: 111 | U6: 52 | V6: 163 | W6: 110 | X6: 5 | Y6: 24 | Z6: 99 | AA6: 111 | AB6: 86 | AC6: 58 | AD6: 90 | AE6: 114 | AF6: 48 | AG6: 63 | AH6: 154 | AI6: 90 | AJ6: 45 | AK6: 101
A7: exp_tot_act_R0 | B7: 121
A8: exp_tot_act_R1 | B8: 2184
A9: exp_tot_act_R2 | B9: 1084
A10: exp_tot_act_R3 | B10: 465
A11: exp_total_of_all_regions_activity | B11: 3854
A12: Total_number_of_frames: | B12: 1801
A13: Number_of_movement_frames: | B13: 1559
A14: Number_of_non-movement_frames: | B14: 202
A15: Inactivity_by_epoch: | B15: 3 | C15: 1 | D15: 0 | E15: 0 | F15: 0 | G15: 7 | H15: 0 | I15: 0 | J15: 1 | K15: 0 | L15: 0 | M15: 0 | N15: 1 | O15: 0 | P15: 0 | Q15: 3 | R15: 7 | S15: 0 | T15: 2 | U15: 6 | V15: 0 | W15: 2 | X15: 47 | Y15: 36 | Z15: 5 | AA15: 0 | AB15: 3 | AC15: 11 | AD15: 3 | AE15: 3 | AF15: 26 | AG15: 8 | AH15: 0 | AI15: 0 | AJ15: 23 | AK15: 4
A16: Total_number_of_VALID_frames: | B16: 1761
A17: Proportion_of_VALID_frames: | B17: 0.9777901
A18: Invalid_frame_count_(incorrect_or_too_many_contours): | B18: 40
A19: Proportion_of_Invalid_frames: | B19: 0.022209883
A20: Rejected_contour_count_outisde_regions: | B20: 0
A21: Rejected_contour_count_outisde_mask: | B21: 0
A22: Rejected_contour_count_too_small: | B22: 5503
A23: Rejected_contour_count_too_large: | B23: 30
A26: Video_File_Analysed | B26: IMG_0053_FU_OSP_051222.mp4
A27: R0 | B27: 2 | C27: 9 | D27: 10 | E27: 27 | F27: 37 | G27: 25 | H27: 27 | I27: 12 | J27: 12 | K27: 18 | L27: 23 | M27: 9 | N27: 8 | O27: 22 | P27: 16 | Q27: 38 | R27: 0 | S27: 0 | T27: 10 | U27: 12 | V27: 23 | W27: 18 | X27: 13 | Y27: 20 | Z27: 0 | AA27: 2 | AB27: 7 | AC27: 3 | AD27: 10 | AE27: 4 | AF27: 1 | AG27: 8 | AH27: 5 | AI27: 0 | AJ27: 0 | AK27: 3
A28: R1 | B28: 41 | C28: 104 | D28: 118 | E28: 84 | F28: 89 | G28: 117 | H28: 134 | I28: 89 | J28: 80 | K28: 41 | L28: 51 | M28: 41 | N28: 55 | O28: 122 | P28: 68 | Q28: 69 | R28: 27 | S28: 0 | T28: 35 | U28: 60 | V28: 39 | W28: 62 | X28: 58 | Y28: 36 | Z28: 19 | AA28: 41 | AB28: 76 | AC28: 81 | AD28: 117 | AE28: 111 | AF28: 10 | AG28: 81 | AH28: 62 | AI28: 48 | AJ28: 47 | AK28: 76
A29: R2 | B29: 20 | C29: 61 | D29: 47 | E29: 75 | F29: 58 | G29: 20 | H29: 2 | I29: 33 | J29: 21 | K29: 7 | L29: 23 | M29: 32 | N29: 56 | O29: 13 | P29: 49 | Q29: 2 | R29: 1 | S29: 0 | T29: 11 | U29: 35 | V29: 21 | W29: 9 | X29: 6 | Y29: 21 | Z29: 0 | AA29: 0 | AB29: 0 | AC29: 3 | AD29: 2 | AE29: 0 | AF29: 9 | AG29: 7 | AH29: 5 | AI29: 0 | AJ29: 14 | AK29: 2
A30: R3 | B30: 1 | C30: 7 | D30: 6 | E30: 10 | F30: 4 | G30: 4 | H30: 0 | I30: 20 | J30: 12 | K30: 2 | L30: 0 | M30: 1 | N30: 11 | O30: 0 | P30: 12 | Q30: 0 | R30: 34 | S30: 32 | T30: 1 | U30: 16 | V30: 6 | W30: 51 | X30: 4 | Y30: 0 | Z30: 0 | AA30: 0 | AB30: 0 | AC30: 0 | AD30: 0 | AE30: 0 | AF30: 2 | AG30: 0 | AH30: 0 | AI30: 0 | AJ30: 4 | AK30: 0
A31: tot_reg_act_per_matrix | B31: 64 | C31: 181 | D31: 181 | E31: 196 | F31: 188 | G31: 166 | H31: 163 | I31: 154 | J31: 125 | K31: 68 | L31: 97 | M31: 83 | N31: 130 | O31: 157 | P31: 145 | Q31: 109 | R31: 62 | S31: 32 | T31: 57 | U31: 123 | V31: 89 | W31: 140 | X31: 81 | Y31: 77 | Z31: 19 | AA31: 43 | AB31: 83 | AC31: 87 | AD31: 129 | AE31: 115 | AF31: 22 | AG31: 96 | AH31: 72 | AI31: 48 | AJ31: 65 | AK31: 81
A32: exp_tot_act_R0 | B32: 434
A33: exp_tot_act_R1 | B33: 2389
A34: exp_tot_act_R2 | B34: 665
A35: exp_tot_act_R3 | B35: 240
A36: exp_total_of_all_regions_activity | B36: 3728
A37: Total_number_of_frames: | B37: 1801
A38: Number_of_movement_frames: | B38: 1587
A39: Number_of_non-movement_frames: | B39: 202
A40: Inactivity_by_epoch: | B40: 11 | C40: 0 | D40: 0 | E40: 0 | F40: 0 | G40: 0 | H40: 1 | I40: 0 | J40: 0 | K40: 1 | L40: 0 | M40: 2 | N40: 0 | O40: 0 | P40: 0 | Q40: 0 | R40: 10 | S40: 20 | T40: 11 | U40: 0 | V40: 0 | W40: 0 | X40: 18 | Y40: 8 | Z40: 32 | AA40: 19 | AB40: 0 | AC40: 0 | AD40: 2 | AE40: 6 | AF40: 26 | AG40: 4 | AH40: 5 | AI40: 14 | AJ40: 8 | AK40: 4
A41: Total_number_of_VALID_frames: | B41: 1789
A42: Proportion_of_VALID_frames: | B42: 0.99333704
...

Sheet H

Sheet I

Sheet J

Sheet K

Sheet L

Sheet M

Sheet N

Sheet O

Sheet P

Sheet Q

Sheet R

Sheet S
A1: S

Sheet T

Sheet summ tots
C1: A | D1: B | E1: C | F1: D | G1: E | H1: F | I1: G | J1: H | K1: I | L1: J | M1: K | N1: L | O1: M | P1: N | Q1: O | R1: P | S1: Q | T1: R | U1: S | V1: T
B2: run | C2: ='file combos'!D13 -> FAUT | D2: ='file combos'!E13 -> FAP3 | E2: ='file combos'!F13 -> FAOSP | F2: ='file combos'!G13 -> 0 | G2: ='file combos'!H13 -> FUUT | H2: ='file combos'!I13 -> FUP3 | I2: ='file combos'!J13 -> FUOSP | J2: ='file combos'!K13 -> 0 | ... V2: ='file combos'!W13 -> 0
B3: 1 | C3: =A!B11 -> 2432 | D3: =B!B11 -> 3701 | E3: ='C'!B11 -> 1994 | F3: =D!B11 -> 0 | G3: =E!$B$11 -> 1962 | H3: =F!B11 -> 3149 | I3: =G!B11 -> 3854 | J3: =H!B11 -> 0 | K3: =I!B11 -> 0 | L3: =J!B11 -> 0 | M3: =K!B11 -> 0 | N3: =L!B11 -> 0 | O3: =M!B11 -> 0 | P3: =N!B11 -> 0 | Q3: =O!B11 -> 0 | R3: =P!B11 -> 0 | S3: =Q!B11 -> 0 | T3: ='R'!B11 -> 0 | U3: =S!B11 -> 0 | V3: =T!B11 -> 0
B4: 2 | C4: =OFFSET(A!$B$11,(ROW()-3)*25,0) -> 1823 | D4: =OFFSET(B!$B$11,(ROW()-3)*25,0) -> 4374 | E4: =OFFSET('C'!$B$11,(ROW()-3)*25,0) -> 2169 | F4: =OFFSET(D!$B$11,(ROW()-3)*25,0) -> 0 | G4: =OFFSET(E!$B$11,(ROW()-3)*25,0) -> 1415 | H4: =OFFSET(F!$B$11,(ROW()-3)*25,0) -> 4670 | I4: =OFFSET(G!$B$11,(ROW()-3)*25,0) -> 3728 | J4: =OFFSET(H!$B$11,(ROW()-3)*25,0) -> 0 | K4: =OFFSET(I!$B$11,(ROW()-3)*25,0) -> 0 | L4: =OFFSET(J!$B$11,(ROW()-3)*25,0) -> 0 | M4: =OFFSET(K!$B$11,(ROW()-3)*25,0) -> 0 | N4: =OFFSET(L!$B$11,(ROW()-3)*25,0) -> 0 | O4: =OFFSET(M!$B$11,(ROW()-3)*25,0) -> 0 | P4: =OFFSET(M!$B$11,(ROW()-3)*25,0) -> 0 | Q4: =OFFSET(O!$B$11,(ROW()-3)*25,0) -> 0 | R4: =OFFSET(P!$B$11,(ROW()-3)*25,0) -> 0 | S4: =OFFSET(Q!$B$11,(ROW()-3)*25,0) -> 0 | T4: =OFFSET('R'!$B$11,(ROW()-3)*25,0) -> 0 | U4: =OFFSET(S!$B$11,(ROW()-3)*25,0) -> 0 | V4: =OFFSET(T!$B$11,(ROW()-3)*25,0) -> 0
B5: 3 | C5: =OFFSET(A!$B$11,(ROW()-3)*25,0) -> 966 | D5: =OFFSET(B!$B$11,(ROW()-3)*25,0) -> 3997 | E5: =OFFSET('C'!$B$11,(ROW()-3)*25,0) -> 2607 | F5: =OFFSET(D!$B$11,(ROW()-3)*25,0) -> 0 | G5: =OFFSET(E!$B$11,(ROW()-3)*25,0) -> 528 | H5: =OFFSET(F!$B$11,(ROW()-3)*25,0) -> 3220 | I5: =OFFSET(G!$B$11,(ROW()-3)*25,0) -> 5019 | J5: =OFFSET(H!$B$11,(ROW()-3)*25,0) -> 0 | K5: =OFFSET(I!$B$11,(ROW()-3)*25,0) -> 0 | L5: =OFFSET(J!$B$11,(ROW()-3)*25,0) -> 0 | M5: =OFFSET(K!$B$11,(ROW()-3)*25,0) -> 0 | N5: =OFFSET(L!$B$11,(ROW()-3)*25,0) -> 0 | O5: =OFFSET(M!$B$11,(ROW()-3)*25,0) -> 0 | P5: =OFFSET(M!$B$11,(ROW()-3)*25,0) -> 0 | Q5: =OFFSET(O!$B$11,(ROW()-3)*25,0) -> 0 | R5: =OFFSET(P!$B$11,(ROW()-3)*25,0) -> 0 | S5: =OFFSET(Q!$B$11,(ROW()-3)*25,0) -> 0 | T5: =OFFSET('R'!$B$11,(ROW()-3)*25,0) -> 0 | U5: =OFFSET(S!$B$11,(ROW()-3)*25,0) -> 0 | V5: =OFFSET(T!$B$11,(ROW()-3)*25,0) -> 0
B6: 4 | C6: =OFFSET(A!$B$11,(ROW()-3)*25,0) -> 244 | D6: =OFFSET(B!$B$11,(ROW()-3)*25,0) -> 2760 | E6: =OFFSET('C'!$B$11,(ROW()-3)*25,0) -> 2626 | F6: =OFFSET(D!$B$11,(ROW()-3)*25,0) -> 0 | G6: =OFFSET(E!$B$11,(ROW()-3)*25,0) -> 193 | H6: =OFFSET(F!$B$11,(ROW()-3)*25,0) -> 1873 | I6: =OFFSET(G!$B$11,(ROW()-3)*25,0) -> 3217 | J6: =OFFSET(H!$B$11,(ROW()-3)*25,0) -> 0 | K6: =OFFSET(I!$B$11,(ROW()-3)*25,0) -> 0 | L6: =OFFSET(J!$B$11,(ROW()-3)*25,0) -> 0 | M6: =OFFSET(K!$B$11,(ROW()-3)*25,0) -> 0 | N6: =OFFSET(L!$B$11,(ROW()-3)*25,0) -> 0 | O6: =OFFSET(M!$B$11,(ROW()-3)*25,0) -> 0 | P6: =OFFSET(M!$B$11,(ROW()-3)*25,0) -> 0 | Q6: =OFFSET(O!$B$11,(ROW()-3)*25,0) -> 0 | R6: =OFFSET(P!$B$11,(ROW()-3)*25,0) -> 0 | S6: =OFFSET(Q!$B$11,(ROW()-3)*25,0) -> 0 | T6: =OFFSET('R'!$B$11,(ROW()-3)*25,0) -> 0 | U6: =OFFSET(S!$B$11,(ROW()-3)*25,0) -> 0 | V6: =OFFSET(T!$B$11,(ROW()-3)*25,0) -> 0
B7: 5 | C7: =OFFSET(A!$B$11,(ROW()-3)*25,0) -> 1277 | D7: =OFFSET(B!$B$11,(ROW()-3)*25,0) -> 2301 | E7: =OFFSET('C'!$B$11,(ROW()-3)*25,0) -> 2573 | F7: =OFFSET(D!$B$11,(ROW()-3)*25,0) -> 0 | G7: =OFFSET(E!$B$11,(ROW()-3)*25,0) -> 2270 | H7: =OFFSET(F!$B$11,(ROW()-3)*25,0) -> 2745 | I7: =OFFSET(G!$B$11,(ROW()-3)*25,0) -> 3309 | J7: =OFFSET(H!$B$11,(ROW()-3)*25,0) -> 0 | K7: =OFFSET(I!$B$11,(ROW()-3)*25,0) -> 0 | L7: =OFFSET(J!$B$11,(ROW()-3)*25,0) -> 0 | M7: =OFFSET(K!$B$11,(ROW()-3)*25,0) -> 0 | N7: =OFFSET(L!$B$11,(ROW()-3)*25,0) -> 0 | O7: =OFFSET(M!$B$11,(ROW()-3)*25,0) -> 0 | P7: =OFFSET(M!$B$11,(ROW()-3)*25,0) -> 0 | Q7: =OFFSET(O!$B$11,(ROW()-3)*25,0) -> 0 | R7: =OFFSET(P!$B$11,(ROW()-3)*25,0) -> 0 | S7: =OFFSET(Q!$B$11,(ROW()-3)*25,0) -> 0 | T7: =OFFSET('R'!$B$11,(ROW()-3)*25,0) -> 0 | U7: =OFFSET(S!$B$11,(ROW()-3)*25,0) -> 0 | V7: =OFFSET(T!$B$11,(ROW()-3)*25,0) -> 0
B8: 6 | C8: =OFFSET(A!$B$11,(ROW()-3)*25,0) -> 635 | D8: =OFFSET(B!$B$11,(ROW()-3)*25,0) -> 3354 | E8: =OFFSET('C'!$B$11,(ROW()-3)*25,0) -> 2777 | F8: =OFFSET(D!$B$11,(ROW()-3)*25,0) -> 0 | G8: =OFFSET(E!$B$11,(ROW()-3)*25,0) -> 774 | H8: =OFFSET(F!$B$11,(ROW()-3)*25,0) -> 2685 | I8: =OFFSET(G!$B$11,(ROW()-3)*25,0) -> 5036 | J8: =OFFSET(H!$B$11,(ROW()-3)*25,0) -> 0 | K8: =OFFSET(I!$B$11,(ROW()-3)*25,0) -> 0 | L8: =OFFSET(J!$B$11,(ROW()-3)*25,0) -> 0 | M8: =OFFSET(K!$B$11,(ROW()-3)*25,0) -> 0 | N8: =OFFSET(L!$B$11,(ROW()-3)*25,0) -> 0 | O8: =OFFSET(M!$B$11,(ROW()-3)*25,0) -> 0 | P8: =OFFSET(M!$B$11,(ROW()-3)*25,0) -> 0 | Q8: =OFFSET(O!$B$11,(ROW()-3)*25,0) -> 0 | R8: =OFFSET(P!$B$11,(ROW()-3)*25,0) -> 0 | S8: =OFFSET(Q!$B$11,(ROW()-3)*25,0) -> 0 | T8: =OFFSET('R'!$B$11,(ROW()-3)*25,0) -> 0 | U8: =OFFSET(S!$B$11,(ROW()-3)*25,0) -> 0 | V8: =OFFSET(T!$B$11,(ROW()-3)*25,0) -> 0
B9: 7 | C9: =OFFSET(A!$B$11,(ROW()-3)*25,0) -> 1671 | D9: =OFFSET(B!$B$11,(ROW()-3)*25,0) -> 2048 | E9: =OFFSET('C'!$B$11,(ROW()-3)*25,0) -> 2622 | F9: =OFFSET(D!$B$11,(ROW()-3)*25,0) -> 0 | G9: =OFFSET(E!$B$11,(ROW()-3)*25,0) -> 428 | H9: =OFFSET(F!$B$11,(ROW()-3)*25,0) -> 3005 | I9: =OFFSET(G!$B$11,(ROW()-3)*25,0) -> 4712 | J9: =OFFSET(H!$B$11,(ROW()-3)*25,0) -> 0 | K9: =OFFSET(I!$B$11,(ROW()-3)*25,0) -> 0 | L9: =OFFSET(J!$B$11,(ROW()-3)*25,0) -> 0 | M9: =OFFSET(K!$B$11,(ROW()-3)*25,0) -> 0 | N9: =OFFSET(L!$B$11,(ROW()-3)*25,0) -> 0 | O9: =OFFSET(M!$B$11,(ROW()-3)*25,0) -> 0 | P9: =OFFSET(M!$B$11,(ROW()-3)*25,0) -> 0 | Q9: =OFFSET(O!$B$11,(ROW()-3)*25,0) -> 0 | R9: =OFFSET(P!$B$11,(ROW()-3)*25,0) -> 0 | S9: =OFFSET(Q!$B$11,(ROW()-3)*25,0) -> 0 | T9: =OFFSET('R'!$B$11,(ROW()-3)*25,0) -> 0 | U9: =OFFSET(S!$B$11,(ROW()-3)*25,0) -> 0 | V9: =OFFSET(T!$B$11,(ROW()-3)*25,0) -> 0
B10: 8 | C10: =OFFSET(A!$B$11,(ROW()-3)*25,0) -> 2321 | D10: =OFFSET(B!$B$11,(ROW()-3)*25,0) -> 3216 | E10: =OFFSET('C'!$B$11,(ROW()-3)*25,0) -> 3415 | F10: =OFFSET(D!$B$11,(ROW()-3)*25,0) -> 0 | G10: =OFFSET(E!$B$11,(ROW()-3)*25,0) -> 1296 | H10: =OFFSET(F!$B$11,(ROW()-3)*25,0) -> 3231 | I10: =OFFSET(G!$B$11,(ROW()-3)*25,0) -> 4775 | J10: =OFFSET(H!$B$11,(ROW()-3)*25,0) -> 0 | K10: =OFFSET(I!$B$11,(ROW()-3)*25,0) -> 0 | L10: =OFFSET(J!$B$11,(ROW()-3)*25,0) -> 0 | M10: =OFFSET(K!$B$11,(ROW()-3)*25,0) -> 0 | N10: =OFFSET(L!$B$11,(ROW()-3)*25,0) -> 0 | O10: =OFFSET(M!$B$11,(ROW()-3)*25,0) -> 0 | P10: =OFFSET(M!$B$11,(ROW()-3)*25,0) -> 0 | Q10: =OFFSET(O!$B$11,(ROW()-3)*25,0) -> 0 | R10: =OFFSET(P!$B$11,(ROW()-3)*25,0) -> 0 | S10: =OFFSET(Q!$B$11,(ROW()-3)*25,0) -> 0 | T10: =OFFSET('R'!$B$11,(ROW()-3)*25,0) -> 0 | U10: =OFFSET(S!$B$11,(ROW()-3)*25,0) -> 0 | V10: =OFFSET(T!$B$11,(ROW()-3)*25,0) -> 0
B11: 9 | C11: =OFFSET(A!$B$11,(ROW()-3)*25,0) -> 827 | D11: =OFFSET(B!$B$11,(ROW()-3)*25,0) -> 2504 | E11: =OFFSET('C'!$B$11,(ROW()-3)*25,0) -> 2666 | F11: =OFFSET(D!$B$11,(ROW()-3)*25,0) -> 0 | G11: =OFFSET(E!$B$11,(ROW()-3)*25,0) -> 1989 | H11: =OFFSET(F!$B$11,(ROW()-3)*25,0) -> 1847 | I11: =OFFSET(G!$B$11,(ROW()-3)*25,0) -> 5398 | J11: =OFFSET(H!$B$11,(ROW()-3)*25,0) -> 0 | K11: =OFFSET(I!$B$11,(ROW()-3)*25,0) -> 0 | L11: =OFFSET(J!$B$11,(ROW()-3)*25,0) -> 0 | M11: =OFFSET(K!$B$11,(ROW()-3)*25,0) -> 0 | N11: =OFFSET(L!$B$11,(ROW()-3)*25,0) -> 0 | O11: =OFFSET(M!$B$11,(ROW()-3)*25,0) -> 0 | P11: =OFFSET(M!$B$11,(ROW()-3)*25,0) -> 0 | Q11: =OFFSET(O!$B$11,(ROW()-3)*25,0) -> 0 | R11: =OFFSET(P!$B$11,(ROW()-3)*25,0) -> 0 | S11: =OFFSET(Q!$B$11,(ROW()-3)*25,0) -> 0 | T11: =OFFSET('R'!$B$11,(ROW()-3)*25,0) -> 0 | U11: =OFFSET(S!$B$11,(ROW()-3)*25,0) -> 0 | V11: =OFFSET(T!$B$11,(ROW()-3)*25,0) -> 0
B12: 10 | C12: =OFFSET(A!$B$11,(ROW()-3)*25,0) -> 2540 | D12: =OFFSET(B!$B$11,(ROW()-3)*25,0) -> 3190 | E12: =OFFSET('C'!$B$11,(ROW()-3)*25,0) -> 2701 | F12: =OFFSET(D!$B$11,(ROW()-3)*25,0) -> 0 | G12: =OFFSET(E!$B$11,(ROW()-3)*25,0) -> 1872 | H12: =OFFSET(F!$B$11,(ROW()-3)*25,0) -> 874 | I12: =OFFSET(G!$B$11,(ROW()-3)*25,0) -> 3988 | J12: =OFFSET(H!$B$11,(ROW()-3)*25,0) -> 0 | K12: =OFFSET(I!$B$11,(ROW()-3)*25,0) -> 0 | L12: =OFFSET(J!$B$11,(ROW()-3)*25,0) -> 0 | M12: =OFFSET(K!$B$11,(ROW()-3)*25,0) -> 0 | N12: =OFFSET(L!$B$11,(ROW()-3)*25,0) -> 0 | O12: =OFFSET(M!$B$11,(ROW()-3)*25,0) -> 0 | P12: =OFFSET(M!$B$11,(ROW()-3)*25,0) -> 0 | Q12: =OFFSET(O!$B$11,(ROW()-3)*25,0) -> 0 | R12: =OFFSET(P!$B$11,(ROW()-3)*25,0) -> 0 | S12: =OFFSET(Q!$B$11,(ROW()-3)*25,0) -> 0 | T12: =OFFSET('R'!$B$11,(ROW()-3)*25,0) -> 0 | U12: =OFFSET(S!$B$11,(ROW()-3)*25,0) -> 0 | V12: =OFFSET(T!$B$11,(ROW()-3)*25,0) -> 0
B13: 11 | C13: =OFFSET(A!$B$11,(ROW()-3)*25,0) -> 470 | D13: =OFFSET(B!$B$11,(ROW()-3)*25,0) -> 3582 | E13: =OFFSET('C'!$B$11,(ROW()-3)*25,0) -> 2284 | F13: =OFFSET(D!$B$11,(ROW()-3)*25,0) -> 0 | G13: =OFFSET(E!$B$11,(ROW()-3)*25,0) -> 1163 | H13: =OFFSET(F!$B$11,(ROW()-3)*25,0) -> 1719 | I13: =OFFSET(G!$B$11,(ROW()-3)*25,0) -> 3710 | J13: =OFFSET(H!$B$11,(ROW()-3)*25,0) -> 0 | K13: =OFFSET(I!$B$11,(ROW()-3)*25,0) -> 0 | L13: =OFFSET(J!$B$11,(ROW()-3)*25,0) -> 0 | M13: =OFFSET(K!$B$11,(ROW()-3)*25,0) -> 0 | N13: =OFFSET(L!$B$11,(ROW()-3)*25,0) -> 0 | O13: =OFFSET(M!$B$11,(ROW()-3)*25,0) -> 0 | P13: =OFFSET(M!$B$11,(ROW()-3)*25,0) -> 0 | Q13: =OFFSET(O!$B$11,(ROW()-3)*25,0) -> 0 | R13: =OFFSET(P!$B$11,(ROW()-3)*25,0) -> 0 | S13: =OFFSET(Q!$B$11,(ROW()-3)*25,0) -> 0 | T13: =OFFSET('R'!$B$11,(ROW()-3)*25,0) -> 0 | U13: =OFFSET(S!$B$11,(ROW()-3)*25,0) -> 0 | V13: =OFFSET(T!$B$11,(ROW()-3)*25,0) -> 0
B14: 12 | C14: =OFFSET(A!$B$11,(ROW()-3)*25,0) -> 1683 | D14: =OFFSET(B!$B$11,(ROW()-3)*25,0) -> 2937 | E14: =OFFSET('C'!$B$11,(ROW()-3)*25,0) -> 2802 | F14: =OFFSET(D!$B$11,(ROW()-3)*25,0) -> 0 | G14: =OFFSET(E!$B$11,(ROW()-3)*25,0) -> 943 | H14: =OFFSET(F!$B$11,(ROW()-3)*25,0) -> 2932 | I14: =OFFSET(G!$B$11,(ROW()-3)*25,0) -> 4145 | J14: =OFFSET(H!$B$11,(ROW()-3)*25,0) -> 0 | K14: =OFFSET(I!$B$11,(ROW()-3)*25,0) -> 0 | L14: =OFFSET(J!$B$11,(ROW()-3)*25,0) -> 0 | M14: =OFFSET(K!$B$11,(ROW()-3)*25,0) -> 0 | N14: =OFFSET(L!$B$11,(ROW()-3)*25,0) -> 0 | O14: =OFFSET(M!$B$11,(ROW()-3)*25,0) -> 0 | P14: =OFFSET(M!$B$11,(ROW()-3)*25,0) -> 0 | Q14: =OFFSET(O!$B$11,(ROW()-3)*25,0) -> 0 | R14: =OFFSET(P!$B$11,(ROW()-3)*25,0) -> 0 | S14: =OFFSET(Q!$B$11,(ROW()-3)*25,0) -> 0 | T14: =OFFSET('R'!$B$11,(ROW()-3)*25,0) -> 0 | U14: =OFFSET(S!$B$11,(ROW()-3)*25,0) -> 0 | V14: =OFFSET(T!$B$11,(ROW()-3)*25,0) -> 0
B15: 13 | C15: =OFFSET(A!$B$11,(ROW()-3)*25,0) -> 3659 | D15: =OFFSET(B!$B$11,(ROW()-3)*25,0) -> 3694 | E15: =OFFSET('C'!$B$11,(ROW()-3)*25,0) -> 3814 | F15: =OFFSET(D!$B$11,(ROW()-3)*25,0) -> 0 | G15: =OFFSET(E!$B$11,(ROW()-3)*25,0) -> 1369 | H15: =OFFSET(F!$B$11,(ROW()-3)*25,0) -> 3499 | I15: =OFFSET(G!$B$11,(ROW()-3)*25,0) -> 3180 | J15: =OFFSET(H!$B$11,(ROW()-3)*25,0) -> 0 | K15: =OFFSET(I!$B$11,(ROW()-3)*25,0) -> 0 | L15: =OFFSET(J!$B$11,(ROW()-3)*25,0) -> 0 | M15: =OFFSET(K!$B$11,(ROW()-3)*25,0) -> 0 | N15: =OFFSET(L!$B$11,(ROW()-3)*25,0) -> 0 | O15: =OFFSET(M!$B$11,(ROW()-3)*25,0) -> 0 | P15: =OFFSET(M!$B$11,(ROW()-3)*25,0) -> 0 | Q15: =OFFSET(O!$B$11,(ROW()-3)*25,0) -> 0 | R15: =OFFSET(P!$B$11,(ROW()-3)*25,0) -> 0 | S15: =OFFSET(Q!$B$11,(ROW()-3)*25,0) -> 0 | T15: =OFFSET('R'!$B$11,(ROW()-3)*25,0) -> 0 | U15: =OFFSET(S!$B$11,(ROW()-3)*25,0) -> 0 | V15: =OFFSET(T!$B$11,(ROW()-3)*25,0) -> 0
... B18: 16 | C18: =OFFSET(A!$B$11,(ROW()-3)*25,0) -> 1099 | D18: =OFFSET(B!$B$11,(ROW()-3)*25,0) -> 3120 | E18: =OFFSET('C'!$B$11,(ROW()-3)*25,0) -> 3183 | F18: =OFFSET(D!$B$11,(ROW()-3)*25,0) -> 0 | G18: =OFFSET(E!$B$11,(ROW()-3)*25,0) -> 901 | H18: =OFFSET(F!$B$11,(ROW()-3)*25,0) -> 1966 | I18: =OFFSET(G!$B$11,(ROW()-3)*25,0) -> 4067 | J18: =OFFSET(H!$B$11,(ROW()-3)*25,0) -> 0 | K18: =OFFSET(I!$B$11,(ROW()-3)*25,0) -> 0 | L18: =OFFSET(J!$B$11,(ROW()-3)*25,0) -> 0 | M18: =OFFSET(K!$B$11,(ROW()-3)*25,0) -> 0 | N18: =OFFSET(L!$B$11,(ROW()-3)*25,0) -> 0 | O18: =OFFSET(M!$B$11,(ROW()-3)*25,0) -> 0 | P18: =OFFSET(M!$B$11,(ROW()-3)*25,0) -> 0 | Q18: =OFFSET(O!$B$11,(ROW()-3)*25,0) -> 0 | R18: =OFFSET(P!$B$11,(ROW()-3)*25,0) -> 0 | S18: =OFFSET(Q!$B$11,(ROW()-3)*25,0) -> 0 | T18: =OFFSET('R'!$B$11,(ROW()-3)*25,0) -> 0 | U18: =OFFSET(S!$B$11,(ROW()-3)*25,0) -> 0 | V18: =OFFSET(T!$B$11,(ROW()-3)*25,0) -> 0
B19: 17 | C19: =OFFSET(A!$B$11,(ROW()-3)*25,0) -> 2045 | D19: =OFFSET(B!$B$11,(ROW()-3)*25,0) -> 2582 | E19: =OFFSET('C'!$B$11,(ROW()-3)*25,0) -> 1922 | F19: =OFFSET(D!$B$11,(ROW()-3)*25,0) -> 0 | G19: =OFFSET(E!$B$11,(ROW()-3)*25,0) -> 2738 | H19: =OFFSET(F!$B$11,(ROW()-3)*25,0) -> 3062 | I19: =OFFSET(G!$B$11,(ROW()-3)*25,0) -> 3346 | J19: =OFFSET(H!$B$11,(ROW()-3)*25,0) -> 0 | K19: =OFFSET(I!$B$11,(ROW()-3)*25,0) -> 0 | L19: =OFFSET(J!$B$11,(ROW()-3)*25,0) -> 0 | M19: =OFFSET(K!$B$11,(ROW()-3)*25,0) -> 0 | N19: =OFFSET(L!$B$11,(ROW()-3)*25,0) -> 0 | O19: =OFFSET(M!$B$11,(ROW()-3)*25,0) -> 0 | P19: =OFFSET(M!$B$11,(ROW()-3)*25,0) -> 0 | Q19: =OFFSET(O!$B$11,(ROW()-3)*25,0) -> 0 | R19: =OFFSET(P!$B$11,(ROW()-3)*25,0) -> 0 | S19: =OFFSET(Q!$B$11,(ROW()-3)*25,0) -> 0 | T19: =OFFSET('R'!$B$11,(ROW()-3)*25,0) -> 0 | U19: =OFFSET(S!$B$11,(ROW()-3)*25,0) -> 0 | V19: =OFFSET(T!$B$11,(ROW()-3)*25,0) -> 0 | Y19: below is only to be used if grouping susc vs resistant
B20: 18 | C20: =OFFSET(A!$B$11,(ROW()-3)*25,0) -> 1964 | D20: =OFFSET(B!$B$11,(ROW()-3)*25,0) -> 3092 | E20: =OFFSET('C'!$B$11,(ROW()-3)*25,0) -> 3171 | F20: =OFFSET(D!$B$11,(ROW()-3)*25,0) -> 0 | G20: =OFFSET(E!$B$11,(ROW()-3)*25,0) -> 2037 | H20: =OFFSET(F!$B$11,(ROW()-3)*25,0) -> 3226 | I20: =OFFSET(G!$B$11,(ROW()-3)*25,0) -> 4290 | J20: =OFFSET(H!$B$11,(ROW()-3)*25,0) -> 0 | K20: =OFFSET(I!$B$11,(ROW()-3)*25,0) -> 0 | L20: =OFFSET(J!$B$11,(ROW()-3)*25,0) -> 0 | M20: =OFFSET(K!$B$11,(ROW()-3)*25,0) -> 0 | N20: =OFFSET(L!$B$11,(ROW()-3)*25,0) -> 0 | O20: =OFFSET(M!$B$11,(ROW()-3)*25,0) -> 0 | P20: =OFFSET(M!$B$11,(ROW()-3)*25,0) -> 0 | Q20: =OFFSET(O!$B$11,(ROW()-3)*25,0) -> 0 | R20: =OFFSET(P!$B$11,(ROW()-3)*25,0) -> 0 | S20: =OFFSET(Q!$B$11,(ROW()-3)*25,0) -> 0 | T20: =OFFSET('R'!$B$11,(ROW()-3)*25,0) -> 0 | U20: =OFFSET(S!$B$11,(ROW()-3)*25,0) -> 0 | V20: =OFFSET(T!$B$11,(ROW()-3)*25,0) -> 0
B21: 19 | C21: =OFFSET(A!$B$11,(ROW()-3)*25,0) -> 2062 | D21: =OFFSET(B!$B$11,(ROW()-3)*25,0) -> 3539 | E21: =OFFSET('C'!$B$11,(ROW()-3)*25,0) -> 3215 | F21: =OFFSET(D!$B$11,(ROW()-3)*25,0) -> 0 | G21: =OFFSET(E!$B$11,(ROW()-3)*25,0) -> 2454 | H21: =OFFSET(F!$B$11,(ROW()-3)*25,0) -> 4190 | I21: =OFFSET(G!$B$11,(ROW()-3)*25,0) -> 4372 | J21: =OFFSET(H!$B$11,(ROW()-3)*25,0) -> 0 | K21: =OFFSET(I!$B$11,(ROW()-3)*25,0) -> 0 | L21: =OFFSET(J!$B$11,(ROW()-3)*25,0) -> 0 | M21: =OFFSET(K!$B$11,(ROW()-3)*25,0) -> 0 | N21: =OFFSET(L!$B$11,(ROW()-3)*25,0) -> 0 | O21: =OFFSET(M!$B$11,(ROW()-3)*25,0) -> 0 | P21: =OFFSET(M!$B$11,(ROW()-3)*25,0) -> 0 | Q21: =OFFSET(O!$B$11,(ROW()-3)*25,0) -> 0 | R21: =OFFSET(P!$B$11,(ROW()-3)*25,0) -> 0 | S21: =OFFSET(Q!$B$11,(ROW()-3)*25,0) -> 0 | T21: =OFFSET('R'!$B$11,(ROW()-3)*25,0) -> 0 | U21: =OFFSET(S!$B$11,(ROW()-3)*25,0) -> 0 | V21: =OFFSET(T!$B$11,(ROW()-3)*25,0) -> 0 | Y21: Combine Susceptible strains and resistant strains
B22: 20 | C22: =OFFSET(A!$B$11,(ROW()-3)*25,0) -> 2502 | D22: =OFFSET(B!$B$11,(ROW()-3)*25,0) -> 2864 | E22: =OFFSET('C'!$B$11,(ROW()-3)*25,0) -> 2986 | F22: =OFFSET(D!$B$11,(ROW()-3)*25,0) -> 0 | G22: =OFFSET(E!$B$11,(ROW()-3)*25,0) -> 2194 | H22: =OFFSET(F!$B$11,(ROW()-3)*25,0) -> 2149 | I22: =OFFSET(G!$B$11,(ROW()-3)*25,0) -> 4627 | J22: =OFFSET(H!$B$11,(ROW()-3)*25,0) -> 0 | K22: =OFFSET(I!$B$11,(ROW()-3)*25,0) -> 0 | L22: =OFFSET(J!$B$11,(ROW()-3)*25,0) -> 0 | M22: =OFFSET(K!$B$11,(ROW()-3)*25,0) -> 0 | N22: =OFFSET(L!$B$11,(ROW()-3)*25,0) -> 0 | O22: =OFFSET(M!$B$11,(ROW()-3)*25,0) -> 0 | P22: =OFFSET(M!$B$11,(ROW()-3)*25,0) -> 0 | Q22: =OFFSET(O!$B$11,(ROW()-3)*25,0) -> 0 | R22: =OFFSET(P!$B$11,(ROW()-3)*25,0) -> 0 | S22: =OFFSET(Q!$B$11,(ROW()-3)*25,0) -> 0 | T22: =OFFSET('R'!$B$11,(ROW()-3)*25,0) -> 0 | U22: =OFFSET(S!$B$11,(ROW()-3)*25,0) -> 0 | V22: =OFFSET(T!$B$11,(ROW()-3)*25,0) -> 0 | Y22: S-UT | Z22: S-P3 | AA22: S IG2 | AB22: s-P2 | AC22: S-OS | AD22: R_UT | AE22: R_P3 | AF22: R_IG2 | AG22: R-P2 | AH22: R-OS
B23: 21 | C23: =OFFSET(A!$B$11,(ROW()-3)*25,0) -> 1751 | D23: =OFFSET(B!$B$11,(ROW()-3)*25,0) -> 3190 | E23: =OFFSET('C'!$B$11,(ROW()-3)*25,0) -> 3775 | F23: =OFFSET(D!$B$11,(ROW()-3)*25,0) -> 0 | G23: =OFFSET(E!$B$11,(ROW()-3)*25,0) -> 2902 | H23: =OFFSET(F!$B$11,(ROW()-3)*25,0) -> 2029 | I23: =OFFSET(G!$B$11,(ROW()-3)*25,0) -> 4951 | J23: =OFFSET(H!$B$11,(ROW()-3)*25,0) -> 0 | K23: =OFFSET(I!$B$11,(ROW()-3)*25,0) -> 0 | L23: =OFFSET(J!$B$11,(ROW()-3)*25,0) -> 0 | M23: =OFFSET(K!$B$11,(ROW()-3)*25,0) -> 0 | N23: =OFFSET(L!$B$11,(ROW()-3)*25,0) -> 0 | O23: =OFFSET(M!$B$11,(ROW()-3)*25,0) -> 0 | P23: =OFFSET(M!$B$11,(ROW()-3)*25,0) -> 0 | Q23: =OFFSET(O!$B$11,(ROW()-3)*25,0) -> 0 | R23: =OFFSET(P!$B$11,(ROW()-3)*25,0) -> 0 | S23: =OFFSET(Q!$B$11,(ROW()-3)*25,0) -> 0 | T23: =OFFSET('R'!$B$11,(ROW()-3)*25,0) -> 0 | U23: =OFFSET(S!$B$11,(ROW()-3)*25,0) -> 0 | V23: =OFFSET(T!$B$11,(ROW()-3)*25,0) -> 0 | X23: mean | Y23: =C54+L54 -> 1811.619 | Z23: =M54+D54 -> 3152.4286 | AA23: =N54+E54 -> 2869.4286 | AB23: =F54+K54 -> 0 | AC23: =G54+L54 -> 1527.6667 | AD23: =I54+F54 -> 4199.1905 | AE23: =J54+G54 -> 1527.6667 | AF23: =K54+H54 -> 2778.381 | AG23: =P54+U54 -> 0 | AH23: =Q54+V54 -> 0
B24: 22 | C24: =OFFSET(A!$B$11,(ROW()-3)*25,0) -> 0 | D24: =OFFSET(B!$B$11,(ROW()-3)*25,0) -> 0 | E24: =OFFSET('C'!$B$11,(ROW()-3)*25,0) -> 0 | F24: =OFFSET(D!$B$11,(ROW()-3)*25,0) -> 0 | G24: =OFFSET(E!$B$11,(ROW()-3)*25,0) -> 0 | H24: =OFFSET(F!$B$11,(ROW()-3)*25,0) -> 0 | I24: =OFFSET(G!$B$11,(ROW()-3)*25,0) -> 0 | J24: =OFFSET(H!$B$11,(ROW()-3)*25,0) -> 0 | K24: =OFFSET(I!$B$11,(ROW()-3)*25,0) -> 0 | L24: =OFFSET(J!$B$11,(ROW()-3)*25,0) -> 0 | M24: =OFFSET(K!$B$11,(ROW()-3)*25,0) -> 0 | N24: =OFFSET(L!$B$11,(ROW()-3)*25,0) -> 0 | O24: =OFFSET(M!$B$11,(ROW()-3)*25,0) -> 0 | P24: =OFFSET(M!$B$11,(ROW()-3)*25,0) -> 0 | Q24: =OFFSET(O!$B$11,(ROW()-3)*25,0) -> 0 | R24: =OFFSET(P!$B$11,(ROW()-3)*25,0) -> 0 | S24: =OFFSET(Q!$B$11,(ROW()-3)*25,0) -> 0 | T24: =OFFSET('R'!$B$11,(ROW()-3)*25,0) -> 0 | U24: =OFFSET(S!$B$11,(ROW()-3)*25,0) -> 0 | V24: =OFFSET(T!$B$11,(ROW()-3)*25,0) -> 0
B25: 23 | C25: =OFFSET(A!$B$11,(ROW()-3)*25,0) -> 0 | D25: =OFFSET(B!$B$11,(ROW()-3)*25,0) -> 0 | E25: =OFFSET('C'!$B$11,(ROW()-3)*25,0) -> 0 | F25: =OFFSET(D!$B$11,(ROW()-3)*25,0) -> 0 | G25: =OFFSET(E!$B$11,(ROW()-3)*25,0) -> 0 | H25: =OFFSET(F!$B$11,(ROW()-3)*25,0) -> 0 | I25: =OFFSET(G!$B$11,(ROW()-3)*25,0) -> 0 | J25: =OFFSET(H!$B$11,(ROW()-3)*25,0) -> 0 | K25: =OFFSET(I!$B$11,(ROW()-3)*25,0) -> 0 | L25: =OFFSET(J!$B$11,(ROW()-3)*25,0) -> 0 | M25: =OFFSET(K!$B$11,(ROW()-3)*25,0) -> 0 | N25: =OFFSET(L!$B$11,(ROW()-3)*25,0) -> 0 | O25: =OFFSET(M!$B$11,(ROW()-3)*25,0) -> 0 | P25: =OFFSET(M!$B$11,(ROW()-3)*25,0) -> 0 | Q25: =OFFSET(O!$B$11,(ROW()-3)*25,0) -> 0 | R25: =OFFSET(P!$B$11,(ROW()-3)*25,0) -> 0 | S25: =OFFSET(Q!$B$11,(ROW()-3)*25,0) -> 0 | T25: =OFFSET('R'!$B$11,(ROW()-3)*25,0) -> 0 | U25: =OFFSET(S!$B$11,(ROW()-3)*25,0) -> 0 | V25: =OFFSET(T!$B$11,(ROW()-3)*25,0) -> 0
B26: 24 | C26: =OFFSET(A!$B$11,(ROW()-3)*25,0) -> 0 | D26: =OFFSET(B!$B$11,(ROW()-3)*25,0) -> 0 | E26: =OFFSET('C'!$B$11,(ROW()-3)*25,0) -> 0 | F26: =OFFSET(D!$B$11,(ROW()-3)*25,0) -> 0 | G26: =OFFSET(E!$B$11,(ROW()-3)*25,0) -> 0 | H26: =OFFSET(F!$B$11,(ROW()-3)*25,0) -> 0 | I26: =OFFSET(G!$B$11,(ROW()-3)*25,0) -> 0 | J26: =OFFSET(H!$B$11,(ROW()-3)*25,0) -> 0 | K26: =OFFSET(I!$B$11,(ROW()-3)*25,0) -> 0 | L26: =OFFSET(J!$B$11,(ROW()-3)*25,0) -> 0 | M26: =OFFSET(K!$B$11,(ROW()-3)*25,0) -> 0 | N26: =OFFSET(L!$B$11,(ROW()-3)*25,0) -> 0 | O26: =OFFSET(M!$B$11,(ROW()-3)*25,0) -> 0 | P26: =OFFSET(M!$B$11,(ROW()-3)*25,0) -> 0 | Q26: =OFFSET(O!$B$11,(ROW()-3)*25,0) -> 0 | R26: =OFFSET(P!$B$11,(ROW()-3)*25,0) -> 0 | S26: =OFFSET(Q!$B$11,(ROW()-3)*25,0) -> 0 | T26: =OFFSET('R'!$B$11,(ROW()-3)*25,0) -> 0 | U26: =OFFSET(S!$B$11,(ROW()-3)*25,0) -> 0 | V26: =OFFSET(T!$B$11,(ROW()-3)*25,0) -> 0
B27: 25 | C27: =OFFSET(A!$B$11,(ROW()-3)*25,0) -> 0 | D27: =OFFSET(B!$B$11,(ROW()-3)*25,0) -> 0 | E27: =OFFSET('C'!$B$11,(ROW()-3)*25,0) -> 0 | F27: =OFFSET(D!$B$11,(ROW()-3)*25,0) -> 0 | G27: =OFFSET(E!$B$11,(ROW()-3)*25,0) -> 0 | H27: =OFFSET(F!$B$11,(ROW()-3)*25,0) -> 0 | I27: =OFFSET(G!$B$11,(ROW()-3)*25,0) -> 0 | J27: =OFFSET(H!$B$11,(ROW()-3)*25,0) -> 0 | K27: =OFFSET(I!$B$11,(ROW()-3)*25,0) -> 0 | L27: =OFFSET(J!$B$11,(ROW()-3)*25,0) -> 0 | M27: =OFFSET(K!$B$11,(ROW()-3)*25,0) -> 0 | N27: =OFFSET(L!$B$11,(ROW()-3)*25,0) -> 0 | O27: =OFFSET(M!$B$11,(ROW()-3)*25,0) -> 0 | P27: =OFFSET(M!$B$11,(ROW()-3)*25,0) -> 0 | Q27: =OFFSET(O!$B$11,(ROW()-3)*25,0) -> 0 | R27: =OFFSET(P!$B$11,(ROW()-3)*25,0) -> 0 | S27: =OFFSET(Q!$B$11,(ROW()-3)*25,0) -> 0 | T27: =OFFSET('R'!$B$11,(ROW()-3)*25,0) -> 0 | U27: =OFFSET(S!$B$11,(ROW()-3)*25,0) -> 0 | V27: =OFFSET(T!$B$11,(ROW()-3)*25,0) -> 0
B28: 26 | C28: =OFFSET(A!$B$11,(ROW()-3)*25,0) -> 0 | D28: =OFFSET(B!$B$11,(ROW()-3)*25,0) -> 0 | E28: =OFFSET('C'!$B$11,(ROW()-3)*25,0) -> 0 | F28: =OFFSET(D!$B$11,(ROW()-3)*25,0) -> 0 | G28: =OFFSET(E!$B$11,(ROW()-3)*25,0) -> 0 | H28: =OFFSET(F!$B$11,(ROW()-3)*25,0) -> 0 | I28: =OFFSET(G!$B$11,(ROW()-3)*25,0) -> 0 | J28: =OFFSET(H!$B$11,(ROW()-3)*25,0) -> 0 | K28: =OFFSET(I!$B$11,(ROW()-3)*25,0) -> 0 | L28: =OFFSET(J!$B$11,(ROW()-3)*25,0) -> 0 | M28: =OFFSET(K!$B$11,(ROW()-3)*25,0) -> 0 | N28: =OFFSET(L!$B$11,(ROW()-3)*25,0) -> 0 | O28: =OFFSET(M!$B$11,(ROW()-3)*25,0) -> 0 | P28: =OFFSET(M!$B$11,(ROW()-3)*25,0) -> 0 | Q28: =OFFSET(O!$B$11,(ROW()-3)*25,0) -> 0 | R28: =OFFSET(P!$B$11,(ROW()-3)*25,0) -> 0 | S28: =OFFSET(Q!$B$11,(ROW()-3)*25,0) -> 0 | T28: =OFFSET('R'!$B$11,(ROW()-3)*25,0) -> 0 | U28: =OFFSET(S!$B$11,(ROW()-3)*25,0) -> 0 | V28: =OFFSET(T!$B$11,(ROW()-3)*25,0) -> 0
